[2024-09-16T21:00:50.859+0000] {processor.py:161} INFO - Started process (PID=59) to work on /opt/airflow/dags/dag.py
[2024-09-16T21:00:50.861+0000] {processor.py:830} INFO - Processing file /opt/airflow/dags/dag.py for tasks to queue
[2024-09-16T21:00:50.864+0000] {logging_mixin.py:188} INFO - [2024-09-16T21:00:50.863+0000] {dagbag.py:545} INFO - Filling up the DagBag from /opt/airflow/dags/dag.py
[2024-09-16T21:00:54.705+0000] {logging_mixin.py:188} INFO - [2024-09-16T21:00:54.703+0000] {dagbag.py:355} ERROR - Failed to import: /opt/airflow/dags/dag.py
Traceback (most recent call last):
  File "/home/airflow/.local/lib/python3.12/site-packages/airflow/models/dagbag.py", line 351, in parse
    loader.exec_module(new_module)
  File "<frozen importlib._bootstrap_external>", line 995, in exec_module
  File "<frozen importlib._bootstrap>", line 488, in _call_with_frames_removed
  File "/opt/airflow/dags/dag.py", line 8, in <module>
    with DAG(
         ^^^^
  File "/home/airflow/.local/lib/python3.12/site-packages/airflow/models/dag.py", line 519, in __init__
    validate_key(dag_id)
  File "/home/airflow/.local/lib/python3.12/site-packages/airflow/utils/helpers.py", line 57, in validate_key
    raise AirflowException(
airflow.exceptions.AirflowException: The key '' has to be made of alphanumeric characters, dashes, dots and underscores exclusively
[2024-09-16T21:00:54.706+0000] {processor.py:842} WARNING - No viable dags retrieved from /opt/airflow/dags/dag.py
[2024-09-16T21:00:54.759+0000] {processor.py:183} INFO - Processing /opt/airflow/dags/dag.py took 3.919 seconds
[2024-09-16T21:01:23.996+0000] {processor.py:161} INFO - Started process (PID=41) to work on /opt/airflow/dags/dag.py
[2024-09-16T21:01:23.999+0000] {processor.py:830} INFO - Processing file /opt/airflow/dags/dag.py for tasks to queue
[2024-09-16T21:01:24.007+0000] {logging_mixin.py:188} INFO - [2024-09-16T21:01:24.006+0000] {dagbag.py:545} INFO - Filling up the DagBag from /opt/airflow/dags/dag.py
[2024-09-16T21:01:24.461+0000] {logging_mixin.py:188} INFO - [2024-09-16T21:01:24.459+0000] {dagbag.py:355} ERROR - Failed to import: /opt/airflow/dags/dag.py
Traceback (most recent call last):
  File "/home/airflow/.local/lib/python3.12/site-packages/airflow/models/dagbag.py", line 351, in parse
    loader.exec_module(new_module)
  File "<frozen importlib._bootstrap_external>", line 995, in exec_module
  File "<frozen importlib._bootstrap>", line 488, in _call_with_frames_removed
  File "/opt/airflow/dags/dag.py", line 8, in <module>
    with DAG(
         ^^^^
  File "/home/airflow/.local/lib/python3.12/site-packages/airflow/models/dag.py", line 519, in __init__
    validate_key(dag_id)
  File "/home/airflow/.local/lib/python3.12/site-packages/airflow/utils/helpers.py", line 57, in validate_key
    raise AirflowException(
airflow.exceptions.AirflowException: The key '' has to be made of alphanumeric characters, dashes, dots and underscores exclusively
[2024-09-16T21:01:24.462+0000] {processor.py:842} WARNING - No viable dags retrieved from /opt/airflow/dags/dag.py
[2024-09-16T21:01:24.481+0000] {processor.py:183} INFO - Processing /opt/airflow/dags/dag.py took 0.499 seconds
[2024-09-16T21:01:54.611+0000] {processor.py:161} INFO - Started process (PID=49) to work on /opt/airflow/dags/dag.py
[2024-09-16T21:01:54.611+0000] {processor.py:830} INFO - Processing file /opt/airflow/dags/dag.py for tasks to queue
[2024-09-16T21:01:54.613+0000] {logging_mixin.py:188} INFO - [2024-09-16T21:01:54.612+0000] {dagbag.py:545} INFO - Filling up the DagBag from /opt/airflow/dags/dag.py
[2024-09-16T21:01:55.113+0000] {logging_mixin.py:188} INFO - [2024-09-16T21:01:55.111+0000] {dagbag.py:355} ERROR - Failed to import: /opt/airflow/dags/dag.py
Traceback (most recent call last):
  File "/home/airflow/.local/lib/python3.12/site-packages/airflow/models/dagbag.py", line 351, in parse
    loader.exec_module(new_module)
  File "<frozen importlib._bootstrap_external>", line 995, in exec_module
  File "<frozen importlib._bootstrap>", line 488, in _call_with_frames_removed
  File "/opt/airflow/dags/dag.py", line 8, in <module>
    with DAG(
         ^^^^
  File "/home/airflow/.local/lib/python3.12/site-packages/airflow/models/dag.py", line 519, in __init__
    validate_key(dag_id)
  File "/home/airflow/.local/lib/python3.12/site-packages/airflow/utils/helpers.py", line 57, in validate_key
    raise AirflowException(
airflow.exceptions.AirflowException: The key '' has to be made of alphanumeric characters, dashes, dots and underscores exclusively
[2024-09-16T21:01:55.113+0000] {processor.py:842} WARNING - No viable dags retrieved from /opt/airflow/dags/dag.py
[2024-09-16T21:01:55.130+0000] {processor.py:183} INFO - Processing /opt/airflow/dags/dag.py took 0.526 seconds
[2024-09-16T21:02:25.218+0000] {processor.py:161} INFO - Started process (PID=57) to work on /opt/airflow/dags/dag.py
[2024-09-16T21:02:25.219+0000] {processor.py:830} INFO - Processing file /opt/airflow/dags/dag.py for tasks to queue
[2024-09-16T21:02:25.220+0000] {logging_mixin.py:188} INFO - [2024-09-16T21:02:25.220+0000] {dagbag.py:545} INFO - Filling up the DagBag from /opt/airflow/dags/dag.py
[2024-09-16T21:02:25.695+0000] {logging_mixin.py:188} INFO - [2024-09-16T21:02:25.693+0000] {dagbag.py:355} ERROR - Failed to import: /opt/airflow/dags/dag.py
Traceback (most recent call last):
  File "/home/airflow/.local/lib/python3.12/site-packages/airflow/models/dagbag.py", line 351, in parse
    loader.exec_module(new_module)
  File "<frozen importlib._bootstrap_external>", line 995, in exec_module
  File "<frozen importlib._bootstrap>", line 488, in _call_with_frames_removed
  File "/opt/airflow/dags/dag.py", line 8, in <module>
    with DAG(
         ^^^^
  File "/home/airflow/.local/lib/python3.12/site-packages/airflow/models/dag.py", line 519, in __init__
    validate_key(dag_id)
  File "/home/airflow/.local/lib/python3.12/site-packages/airflow/utils/helpers.py", line 57, in validate_key
    raise AirflowException(
airflow.exceptions.AirflowException: The key '' has to be made of alphanumeric characters, dashes, dots and underscores exclusively
[2024-09-16T21:02:25.695+0000] {processor.py:842} WARNING - No viable dags retrieved from /opt/airflow/dags/dag.py
[2024-09-16T21:02:25.719+0000] {processor.py:183} INFO - Processing /opt/airflow/dags/dag.py took 0.507 seconds
[2024-09-16T21:02:55.842+0000] {processor.py:161} INFO - Started process (PID=66) to work on /opt/airflow/dags/dag.py
[2024-09-16T21:02:55.843+0000] {processor.py:830} INFO - Processing file /opt/airflow/dags/dag.py for tasks to queue
[2024-09-16T21:02:55.845+0000] {logging_mixin.py:188} INFO - [2024-09-16T21:02:55.845+0000] {dagbag.py:545} INFO - Filling up the DagBag from /opt/airflow/dags/dag.py
[2024-09-16T21:02:56.403+0000] {logging_mixin.py:188} INFO - [2024-09-16T21:02:56.401+0000] {dagbag.py:355} ERROR - Failed to import: /opt/airflow/dags/dag.py
Traceback (most recent call last):
  File "/home/airflow/.local/lib/python3.12/site-packages/airflow/models/dagbag.py", line 351, in parse
    loader.exec_module(new_module)
  File "<frozen importlib._bootstrap_external>", line 995, in exec_module
  File "<frozen importlib._bootstrap>", line 488, in _call_with_frames_removed
  File "/opt/airflow/dags/dag.py", line 8, in <module>
    with DAG(
         ^^^^
  File "/home/airflow/.local/lib/python3.12/site-packages/airflow/models/dag.py", line 519, in __init__
    validate_key(dag_id)
  File "/home/airflow/.local/lib/python3.12/site-packages/airflow/utils/helpers.py", line 57, in validate_key
    raise AirflowException(
airflow.exceptions.AirflowException: The key '' has to be made of alphanumeric characters, dashes, dots and underscores exclusively
[2024-09-16T21:02:56.403+0000] {processor.py:842} WARNING - No viable dags retrieved from /opt/airflow/dags/dag.py
[2024-09-16T21:02:56.421+0000] {processor.py:183} INFO - Processing /opt/airflow/dags/dag.py took 0.586 seconds
[2024-09-16T21:03:26.532+0000] {processor.py:161} INFO - Started process (PID=80) to work on /opt/airflow/dags/dag.py
[2024-09-16T21:03:26.533+0000] {processor.py:830} INFO - Processing file /opt/airflow/dags/dag.py for tasks to queue
[2024-09-16T21:03:26.535+0000] {logging_mixin.py:188} INFO - [2024-09-16T21:03:26.534+0000] {dagbag.py:545} INFO - Filling up the DagBag from /opt/airflow/dags/dag.py
[2024-09-16T21:03:26.881+0000] {logging_mixin.py:188} INFO - [2024-09-16T21:03:26.879+0000] {dagbag.py:355} ERROR - Failed to import: /opt/airflow/dags/dag.py
Traceback (most recent call last):
  File "/home/airflow/.local/lib/python3.12/site-packages/airflow/models/dagbag.py", line 351, in parse
    loader.exec_module(new_module)
  File "<frozen importlib._bootstrap_external>", line 995, in exec_module
  File "<frozen importlib._bootstrap>", line 488, in _call_with_frames_removed
  File "/opt/airflow/dags/dag.py", line 8, in <module>
    with DAG(
         ^^^^
  File "/home/airflow/.local/lib/python3.12/site-packages/airflow/models/dag.py", line 519, in __init__
    validate_key(dag_id)
  File "/home/airflow/.local/lib/python3.12/site-packages/airflow/utils/helpers.py", line 57, in validate_key
    raise AirflowException(
airflow.exceptions.AirflowException: The key '' has to be made of alphanumeric characters, dashes, dots and underscores exclusively
[2024-09-16T21:03:26.881+0000] {processor.py:842} WARNING - No viable dags retrieved from /opt/airflow/dags/dag.py
[2024-09-16T21:03:26.903+0000] {processor.py:183} INFO - Processing /opt/airflow/dags/dag.py took 0.375 seconds
[2024-09-16T21:03:57.011+0000] {processor.py:161} INFO - Started process (PID=88) to work on /opt/airflow/dags/dag.py
[2024-09-16T21:03:57.012+0000] {processor.py:830} INFO - Processing file /opt/airflow/dags/dag.py for tasks to queue
[2024-09-16T21:03:57.013+0000] {logging_mixin.py:188} INFO - [2024-09-16T21:03:57.013+0000] {dagbag.py:545} INFO - Filling up the DagBag from /opt/airflow/dags/dag.py
[2024-09-16T21:03:57.342+0000] {logging_mixin.py:188} INFO - [2024-09-16T21:03:57.340+0000] {dagbag.py:355} ERROR - Failed to import: /opt/airflow/dags/dag.py
Traceback (most recent call last):
  File "/home/airflow/.local/lib/python3.12/site-packages/airflow/models/dagbag.py", line 351, in parse
    loader.exec_module(new_module)
  File "<frozen importlib._bootstrap_external>", line 995, in exec_module
  File "<frozen importlib._bootstrap>", line 488, in _call_with_frames_removed
  File "/opt/airflow/dags/dag.py", line 8, in <module>
    with DAG(
         ^^^^
  File "/home/airflow/.local/lib/python3.12/site-packages/airflow/models/dag.py", line 519, in __init__
    validate_key(dag_id)
  File "/home/airflow/.local/lib/python3.12/site-packages/airflow/utils/helpers.py", line 57, in validate_key
    raise AirflowException(
airflow.exceptions.AirflowException: The key '' has to be made of alphanumeric characters, dashes, dots and underscores exclusively
[2024-09-16T21:03:57.342+0000] {processor.py:842} WARNING - No viable dags retrieved from /opt/airflow/dags/dag.py
[2024-09-16T21:03:57.363+0000] {processor.py:183} INFO - Processing /opt/airflow/dags/dag.py took 0.357 seconds
[2024-09-16T21:04:27.485+0000] {processor.py:161} INFO - Started process (PID=96) to work on /opt/airflow/dags/dag.py
[2024-09-16T21:04:27.486+0000] {processor.py:830} INFO - Processing file /opt/airflow/dags/dag.py for tasks to queue
[2024-09-16T21:04:27.488+0000] {logging_mixin.py:188} INFO - [2024-09-16T21:04:27.488+0000] {dagbag.py:545} INFO - Filling up the DagBag from /opt/airflow/dags/dag.py
[2024-09-16T21:04:28.126+0000] {logging_mixin.py:188} INFO - [2024-09-16T21:04:28.124+0000] {dagbag.py:355} ERROR - Failed to import: /opt/airflow/dags/dag.py
Traceback (most recent call last):
  File "/home/airflow/.local/lib/python3.12/site-packages/airflow/models/dagbag.py", line 351, in parse
    loader.exec_module(new_module)
  File "<frozen importlib._bootstrap_external>", line 995, in exec_module
  File "<frozen importlib._bootstrap>", line 488, in _call_with_frames_removed
  File "/opt/airflow/dags/dag.py", line 8, in <module>
    with DAG(
         ^^^^
  File "/home/airflow/.local/lib/python3.12/site-packages/airflow/models/dag.py", line 519, in __init__
    validate_key(dag_id)
  File "/home/airflow/.local/lib/python3.12/site-packages/airflow/utils/helpers.py", line 57, in validate_key
    raise AirflowException(
airflow.exceptions.AirflowException: The key '' has to be made of alphanumeric characters, dashes, dots and underscores exclusively
[2024-09-16T21:04:28.127+0000] {processor.py:842} WARNING - No viable dags retrieved from /opt/airflow/dags/dag.py
[2024-09-16T21:04:28.149+0000] {processor.py:183} INFO - Processing /opt/airflow/dags/dag.py took 0.671 seconds
[2024-09-16T21:04:58.291+0000] {processor.py:161} INFO - Started process (PID=104) to work on /opt/airflow/dags/dag.py
[2024-09-16T21:04:58.292+0000] {processor.py:830} INFO - Processing file /opt/airflow/dags/dag.py for tasks to queue
[2024-09-16T21:04:58.294+0000] {logging_mixin.py:188} INFO - [2024-09-16T21:04:58.294+0000] {dagbag.py:545} INFO - Filling up the DagBag from /opt/airflow/dags/dag.py
[2024-09-16T21:04:59.385+0000] {logging_mixin.py:188} INFO - [2024-09-16T21:04:59.382+0000] {dagbag.py:355} ERROR - Failed to import: /opt/airflow/dags/dag.py
Traceback (most recent call last):
  File "/home/airflow/.local/lib/python3.12/site-packages/airflow/models/dagbag.py", line 351, in parse
    loader.exec_module(new_module)
  File "<frozen importlib._bootstrap_external>", line 995, in exec_module
  File "<frozen importlib._bootstrap>", line 488, in _call_with_frames_removed
  File "/opt/airflow/dags/dag.py", line 8, in <module>
    with DAG(
         ^^^^
  File "/home/airflow/.local/lib/python3.12/site-packages/airflow/models/dag.py", line 519, in __init__
    validate_key(dag_id)
  File "/home/airflow/.local/lib/python3.12/site-packages/airflow/utils/helpers.py", line 57, in validate_key
    raise AirflowException(
airflow.exceptions.AirflowException: The key '' has to be made of alphanumeric characters, dashes, dots and underscores exclusively
[2024-09-16T21:04:59.386+0000] {processor.py:842} WARNING - No viable dags retrieved from /opt/airflow/dags/dag.py
[2024-09-16T21:04:59.409+0000] {processor.py:183} INFO - Processing /opt/airflow/dags/dag.py took 1.125 seconds
[2024-09-16T21:05:29.541+0000] {processor.py:161} INFO - Started process (PID=112) to work on /opt/airflow/dags/dag.py
[2024-09-16T21:05:29.542+0000] {processor.py:830} INFO - Processing file /opt/airflow/dags/dag.py for tasks to queue
[2024-09-16T21:05:29.543+0000] {logging_mixin.py:188} INFO - [2024-09-16T21:05:29.543+0000] {dagbag.py:545} INFO - Filling up the DagBag from /opt/airflow/dags/dag.py
[2024-09-16T21:05:29.983+0000] {logging_mixin.py:188} INFO - [2024-09-16T21:05:29.981+0000] {dagbag.py:355} ERROR - Failed to import: /opt/airflow/dags/dag.py
Traceback (most recent call last):
  File "/home/airflow/.local/lib/python3.12/site-packages/airflow/models/dagbag.py", line 351, in parse
    loader.exec_module(new_module)
  File "<frozen importlib._bootstrap_external>", line 995, in exec_module
  File "<frozen importlib._bootstrap>", line 488, in _call_with_frames_removed
  File "/opt/airflow/dags/dag.py", line 8, in <module>
    with DAG(
         ^^^^
  File "/home/airflow/.local/lib/python3.12/site-packages/airflow/models/dag.py", line 519, in __init__
    validate_key(dag_id)
  File "/home/airflow/.local/lib/python3.12/site-packages/airflow/utils/helpers.py", line 57, in validate_key
    raise AirflowException(
airflow.exceptions.AirflowException: The key '' has to be made of alphanumeric characters, dashes, dots and underscores exclusively
[2024-09-16T21:05:29.983+0000] {processor.py:842} WARNING - No viable dags retrieved from /opt/airflow/dags/dag.py
[2024-09-16T21:05:30.003+0000] {processor.py:183} INFO - Processing /opt/airflow/dags/dag.py took 0.466 seconds
[2024-09-16T21:06:00.117+0000] {processor.py:161} INFO - Started process (PID=120) to work on /opt/airflow/dags/dag.py
[2024-09-16T21:06:00.117+0000] {processor.py:830} INFO - Processing file /opt/airflow/dags/dag.py for tasks to queue
[2024-09-16T21:06:00.119+0000] {logging_mixin.py:188} INFO - [2024-09-16T21:06:00.119+0000] {dagbag.py:545} INFO - Filling up the DagBag from /opt/airflow/dags/dag.py
[2024-09-16T21:06:00.587+0000] {logging_mixin.py:188} INFO - [2024-09-16T21:06:00.584+0000] {dagbag.py:355} ERROR - Failed to import: /opt/airflow/dags/dag.py
Traceback (most recent call last):
  File "/home/airflow/.local/lib/python3.12/site-packages/airflow/models/dagbag.py", line 351, in parse
    loader.exec_module(new_module)
  File "<frozen importlib._bootstrap_external>", line 995, in exec_module
  File "<frozen importlib._bootstrap>", line 488, in _call_with_frames_removed
  File "/opt/airflow/dags/dag.py", line 8, in <module>
    with DAG(
         ^^^^
  File "/home/airflow/.local/lib/python3.12/site-packages/airflow/models/dag.py", line 519, in __init__
    validate_key(dag_id)
  File "/home/airflow/.local/lib/python3.12/site-packages/airflow/utils/helpers.py", line 57, in validate_key
    raise AirflowException(
airflow.exceptions.AirflowException: The key '' has to be made of alphanumeric characters, dashes, dots and underscores exclusively
[2024-09-16T21:06:00.596+0000] {processor.py:842} WARNING - No viable dags retrieved from /opt/airflow/dags/dag.py
[2024-09-16T21:06:00.629+0000] {processor.py:183} INFO - Processing /opt/airflow/dags/dag.py took 0.517 seconds
[2024-09-16T21:06:30.757+0000] {processor.py:161} INFO - Started process (PID=128) to work on /opt/airflow/dags/dag.py
[2024-09-16T21:06:30.757+0000] {processor.py:830} INFO - Processing file /opt/airflow/dags/dag.py for tasks to queue
[2024-09-16T21:06:30.759+0000] {logging_mixin.py:188} INFO - [2024-09-16T21:06:30.759+0000] {dagbag.py:545} INFO - Filling up the DagBag from /opt/airflow/dags/dag.py
[2024-09-16T21:06:31.169+0000] {logging_mixin.py:188} INFO - [2024-09-16T21:06:31.167+0000] {dagbag.py:355} ERROR - Failed to import: /opt/airflow/dags/dag.py
Traceback (most recent call last):
  File "/home/airflow/.local/lib/python3.12/site-packages/airflow/models/dagbag.py", line 351, in parse
    loader.exec_module(new_module)
  File "<frozen importlib._bootstrap_external>", line 995, in exec_module
  File "<frozen importlib._bootstrap>", line 488, in _call_with_frames_removed
  File "/opt/airflow/dags/dag.py", line 8, in <module>
    with DAG(
         ^^^^
  File "/home/airflow/.local/lib/python3.12/site-packages/airflow/models/dag.py", line 519, in __init__
    validate_key(dag_id)
  File "/home/airflow/.local/lib/python3.12/site-packages/airflow/utils/helpers.py", line 57, in validate_key
    raise AirflowException(
airflow.exceptions.AirflowException: The key '' has to be made of alphanumeric characters, dashes, dots and underscores exclusively
[2024-09-16T21:06:31.170+0000] {processor.py:842} WARNING - No viable dags retrieved from /opt/airflow/dags/dag.py
[2024-09-16T21:06:31.190+0000] {processor.py:183} INFO - Processing /opt/airflow/dags/dag.py took 0.438 seconds
[2024-09-16T21:07:01.303+0000] {processor.py:161} INFO - Started process (PID=137) to work on /opt/airflow/dags/dag.py
[2024-09-16T21:07:01.304+0000] {processor.py:830} INFO - Processing file /opt/airflow/dags/dag.py for tasks to queue
[2024-09-16T21:07:01.305+0000] {logging_mixin.py:188} INFO - [2024-09-16T21:07:01.305+0000] {dagbag.py:545} INFO - Filling up the DagBag from /opt/airflow/dags/dag.py
[2024-09-16T21:07:01.772+0000] {logging_mixin.py:188} INFO - [2024-09-16T21:07:01.770+0000] {dagbag.py:355} ERROR - Failed to import: /opt/airflow/dags/dag.py
Traceback (most recent call last):
  File "/home/airflow/.local/lib/python3.12/site-packages/airflow/models/dagbag.py", line 351, in parse
    loader.exec_module(new_module)
  File "<frozen importlib._bootstrap_external>", line 995, in exec_module
  File "<frozen importlib._bootstrap>", line 488, in _call_with_frames_removed
  File "/opt/airflow/dags/dag.py", line 8, in <module>
    with DAG(
         ^^^^
  File "/home/airflow/.local/lib/python3.12/site-packages/airflow/models/dag.py", line 519, in __init__
    validate_key(dag_id)
  File "/home/airflow/.local/lib/python3.12/site-packages/airflow/utils/helpers.py", line 57, in validate_key
    raise AirflowException(
airflow.exceptions.AirflowException: The key '' has to be made of alphanumeric characters, dashes, dots and underscores exclusively
[2024-09-16T21:07:01.773+0000] {processor.py:842} WARNING - No viable dags retrieved from /opt/airflow/dags/dag.py
[2024-09-16T21:07:01.810+0000] {processor.py:183} INFO - Processing /opt/airflow/dags/dag.py took 0.511 seconds
[2024-09-16T21:07:31.935+0000] {processor.py:161} INFO - Started process (PID=146) to work on /opt/airflow/dags/dag.py
[2024-09-16T21:07:31.936+0000] {processor.py:830} INFO - Processing file /opt/airflow/dags/dag.py for tasks to queue
[2024-09-16T21:07:31.938+0000] {logging_mixin.py:188} INFO - [2024-09-16T21:07:31.938+0000] {dagbag.py:545} INFO - Filling up the DagBag from /opt/airflow/dags/dag.py
[2024-09-16T21:07:32.392+0000] {logging_mixin.py:188} INFO - [2024-09-16T21:07:32.390+0000] {dagbag.py:355} ERROR - Failed to import: /opt/airflow/dags/dag.py
Traceback (most recent call last):
  File "/home/airflow/.local/lib/python3.12/site-packages/airflow/models/dagbag.py", line 351, in parse
    loader.exec_module(new_module)
  File "<frozen importlib._bootstrap_external>", line 995, in exec_module
  File "<frozen importlib._bootstrap>", line 488, in _call_with_frames_removed
  File "/opt/airflow/dags/dag.py", line 8, in <module>
    with DAG(
         ^^^^
  File "/home/airflow/.local/lib/python3.12/site-packages/airflow/models/dag.py", line 519, in __init__
    validate_key(dag_id)
  File "/home/airflow/.local/lib/python3.12/site-packages/airflow/utils/helpers.py", line 57, in validate_key
    raise AirflowException(
airflow.exceptions.AirflowException: The key '' has to be made of alphanumeric characters, dashes, dots and underscores exclusively
[2024-09-16T21:07:32.393+0000] {processor.py:842} WARNING - No viable dags retrieved from /opt/airflow/dags/dag.py
[2024-09-16T21:07:32.409+0000] {processor.py:183} INFO - Processing /opt/airflow/dags/dag.py took 0.481 seconds
[2024-09-16T21:08:02.519+0000] {processor.py:161} INFO - Started process (PID=154) to work on /opt/airflow/dags/dag.py
[2024-09-16T21:08:02.520+0000] {processor.py:830} INFO - Processing file /opt/airflow/dags/dag.py for tasks to queue
[2024-09-16T21:08:02.522+0000] {logging_mixin.py:188} INFO - [2024-09-16T21:08:02.521+0000] {dagbag.py:545} INFO - Filling up the DagBag from /opt/airflow/dags/dag.py
[2024-09-16T21:08:02.977+0000] {logging_mixin.py:188} INFO - [2024-09-16T21:08:02.975+0000] {dagbag.py:355} ERROR - Failed to import: /opt/airflow/dags/dag.py
Traceback (most recent call last):
  File "/home/airflow/.local/lib/python3.12/site-packages/airflow/models/dagbag.py", line 351, in parse
    loader.exec_module(new_module)
  File "<frozen importlib._bootstrap_external>", line 995, in exec_module
  File "<frozen importlib._bootstrap>", line 488, in _call_with_frames_removed
  File "/opt/airflow/dags/dag.py", line 8, in <module>
    with DAG(
         ^^^^
  File "/home/airflow/.local/lib/python3.12/site-packages/airflow/models/dag.py", line 519, in __init__
    validate_key(dag_id)
  File "/home/airflow/.local/lib/python3.12/site-packages/airflow/utils/helpers.py", line 57, in validate_key
    raise AirflowException(
airflow.exceptions.AirflowException: The key '' has to be made of alphanumeric characters, dashes, dots and underscores exclusively
[2024-09-16T21:08:02.978+0000] {processor.py:842} WARNING - No viable dags retrieved from /opt/airflow/dags/dag.py
[2024-09-16T21:08:03.009+0000] {processor.py:183} INFO - Processing /opt/airflow/dags/dag.py took 0.497 seconds
[2024-09-16T21:08:33.133+0000] {processor.py:161} INFO - Started process (PID=162) to work on /opt/airflow/dags/dag.py
[2024-09-16T21:08:33.134+0000] {processor.py:830} INFO - Processing file /opt/airflow/dags/dag.py for tasks to queue
[2024-09-16T21:08:33.135+0000] {logging_mixin.py:188} INFO - [2024-09-16T21:08:33.135+0000] {dagbag.py:545} INFO - Filling up the DagBag from /opt/airflow/dags/dag.py
[2024-09-16T21:08:33.582+0000] {logging_mixin.py:188} INFO - [2024-09-16T21:08:33.581+0000] {dagbag.py:355} ERROR - Failed to import: /opt/airflow/dags/dag.py
Traceback (most recent call last):
  File "/home/airflow/.local/lib/python3.12/site-packages/airflow/models/dagbag.py", line 351, in parse
    loader.exec_module(new_module)
  File "<frozen importlib._bootstrap_external>", line 995, in exec_module
  File "<frozen importlib._bootstrap>", line 488, in _call_with_frames_removed
  File "/opt/airflow/dags/dag.py", line 8, in <module>
    with DAG(
         ^^^^
  File "/home/airflow/.local/lib/python3.12/site-packages/airflow/models/dag.py", line 519, in __init__
    validate_key(dag_id)
  File "/home/airflow/.local/lib/python3.12/site-packages/airflow/utils/helpers.py", line 57, in validate_key
    raise AirflowException(
airflow.exceptions.AirflowException: The key '' has to be made of alphanumeric characters, dashes, dots and underscores exclusively
[2024-09-16T21:08:33.583+0000] {processor.py:842} WARNING - No viable dags retrieved from /opt/airflow/dags/dag.py
[2024-09-16T21:08:33.602+0000] {processor.py:183} INFO - Processing /opt/airflow/dags/dag.py took 0.473 seconds
[2024-09-16T21:09:03.707+0000] {processor.py:161} INFO - Started process (PID=170) to work on /opt/airflow/dags/dag.py
[2024-09-16T21:09:03.708+0000] {processor.py:830} INFO - Processing file /opt/airflow/dags/dag.py for tasks to queue
[2024-09-16T21:09:03.710+0000] {logging_mixin.py:188} INFO - [2024-09-16T21:09:03.709+0000] {dagbag.py:545} INFO - Filling up the DagBag from /opt/airflow/dags/dag.py
[2024-09-16T21:09:04.170+0000] {logging_mixin.py:188} INFO - [2024-09-16T21:09:04.168+0000] {dagbag.py:355} ERROR - Failed to import: /opt/airflow/dags/dag.py
Traceback (most recent call last):
  File "/home/airflow/.local/lib/python3.12/site-packages/airflow/models/dagbag.py", line 351, in parse
    loader.exec_module(new_module)
  File "<frozen importlib._bootstrap_external>", line 995, in exec_module
  File "<frozen importlib._bootstrap>", line 488, in _call_with_frames_removed
  File "/opt/airflow/dags/dag.py", line 8, in <module>
    with DAG(
         ^^^^
  File "/home/airflow/.local/lib/python3.12/site-packages/airflow/models/dag.py", line 519, in __init__
    validate_key(dag_id)
  File "/home/airflow/.local/lib/python3.12/site-packages/airflow/utils/helpers.py", line 57, in validate_key
    raise AirflowException(
airflow.exceptions.AirflowException: The key '' has to be made of alphanumeric characters, dashes, dots and underscores exclusively
[2024-09-16T21:09:04.170+0000] {processor.py:842} WARNING - No viable dags retrieved from /opt/airflow/dags/dag.py
[2024-09-16T21:09:04.191+0000] {processor.py:183} INFO - Processing /opt/airflow/dags/dag.py took 0.489 seconds
[2024-09-16T21:09:34.329+0000] {processor.py:161} INFO - Started process (PID=178) to work on /opt/airflow/dags/dag.py
[2024-09-16T21:09:34.330+0000] {processor.py:830} INFO - Processing file /opt/airflow/dags/dag.py for tasks to queue
[2024-09-16T21:09:34.332+0000] {logging_mixin.py:188} INFO - [2024-09-16T21:09:34.331+0000] {dagbag.py:545} INFO - Filling up the DagBag from /opt/airflow/dags/dag.py
[2024-09-16T21:09:34.695+0000] {logging_mixin.py:188} INFO - [2024-09-16T21:09:34.692+0000] {dagbag.py:355} ERROR - Failed to import: /opt/airflow/dags/dag.py
Traceback (most recent call last):
  File "/home/airflow/.local/lib/python3.12/site-packages/airflow/models/dagbag.py", line 351, in parse
    loader.exec_module(new_module)
  File "<frozen importlib._bootstrap_external>", line 995, in exec_module
  File "<frozen importlib._bootstrap>", line 488, in _call_with_frames_removed
  File "/opt/airflow/dags/dag.py", line 8, in <module>
    with DAG(
         ^^^^
  File "/home/airflow/.local/lib/python3.12/site-packages/airflow/models/dag.py", line 519, in __init__
    validate_key(dag_id)
  File "/home/airflow/.local/lib/python3.12/site-packages/airflow/utils/helpers.py", line 57, in validate_key
    raise AirflowException(
airflow.exceptions.AirflowException: The key '' has to be made of alphanumeric characters, dashes, dots and underscores exclusively
[2024-09-16T21:09:34.696+0000] {processor.py:842} WARNING - No viable dags retrieved from /opt/airflow/dags/dag.py
[2024-09-16T21:09:34.721+0000] {processor.py:183} INFO - Processing /opt/airflow/dags/dag.py took 0.397 seconds
[2024-09-16T21:10:04.833+0000] {processor.py:161} INFO - Started process (PID=186) to work on /opt/airflow/dags/dag.py
[2024-09-16T21:10:04.833+0000] {processor.py:830} INFO - Processing file /opt/airflow/dags/dag.py for tasks to queue
[2024-09-16T21:10:04.835+0000] {logging_mixin.py:188} INFO - [2024-09-16T21:10:04.835+0000] {dagbag.py:545} INFO - Filling up the DagBag from /opt/airflow/dags/dag.py
[2024-09-16T21:10:05.168+0000] {logging_mixin.py:188} INFO - [2024-09-16T21:10:05.166+0000] {dagbag.py:355} ERROR - Failed to import: /opt/airflow/dags/dag.py
Traceback (most recent call last):
  File "/home/airflow/.local/lib/python3.12/site-packages/airflow/models/dagbag.py", line 351, in parse
    loader.exec_module(new_module)
  File "<frozen importlib._bootstrap_external>", line 995, in exec_module
  File "<frozen importlib._bootstrap>", line 488, in _call_with_frames_removed
  File "/opt/airflow/dags/dag.py", line 8, in <module>
    with DAG(
         ^^^^
  File "/home/airflow/.local/lib/python3.12/site-packages/airflow/models/dag.py", line 519, in __init__
    validate_key(dag_id)
  File "/home/airflow/.local/lib/python3.12/site-packages/airflow/utils/helpers.py", line 57, in validate_key
    raise AirflowException(
airflow.exceptions.AirflowException: The key '' has to be made of alphanumeric characters, dashes, dots and underscores exclusively
[2024-09-16T21:10:05.169+0000] {processor.py:842} WARNING - No viable dags retrieved from /opt/airflow/dags/dag.py
[2024-09-16T21:10:05.190+0000] {processor.py:183} INFO - Processing /opt/airflow/dags/dag.py took 0.362 seconds
[2024-09-16T21:10:35.311+0000] {processor.py:161} INFO - Started process (PID=195) to work on /opt/airflow/dags/dag.py
[2024-09-16T21:10:35.312+0000] {processor.py:830} INFO - Processing file /opt/airflow/dags/dag.py for tasks to queue
[2024-09-16T21:10:35.314+0000] {logging_mixin.py:188} INFO - [2024-09-16T21:10:35.313+0000] {dagbag.py:545} INFO - Filling up the DagBag from /opt/airflow/dags/dag.py
[2024-09-16T21:10:35.770+0000] {logging_mixin.py:188} INFO - [2024-09-16T21:10:35.768+0000] {dagbag.py:355} ERROR - Failed to import: /opt/airflow/dags/dag.py
Traceback (most recent call last):
  File "/home/airflow/.local/lib/python3.12/site-packages/airflow/models/dagbag.py", line 351, in parse
    loader.exec_module(new_module)
  File "<frozen importlib._bootstrap_external>", line 995, in exec_module
  File "<frozen importlib._bootstrap>", line 488, in _call_with_frames_removed
  File "/opt/airflow/dags/dag.py", line 8, in <module>
    with DAG(
         ^^^^
  File "/home/airflow/.local/lib/python3.12/site-packages/airflow/models/dag.py", line 519, in __init__
    validate_key(dag_id)
  File "/home/airflow/.local/lib/python3.12/site-packages/airflow/utils/helpers.py", line 57, in validate_key
    raise AirflowException(
airflow.exceptions.AirflowException: The key '' has to be made of alphanumeric characters, dashes, dots and underscores exclusively
[2024-09-16T21:10:35.770+0000] {processor.py:842} WARNING - No viable dags retrieved from /opt/airflow/dags/dag.py
[2024-09-16T21:10:35.795+0000] {processor.py:183} INFO - Processing /opt/airflow/dags/dag.py took 0.489 seconds
[2024-09-16T21:11:05.922+0000] {processor.py:161} INFO - Started process (PID=203) to work on /opt/airflow/dags/dag.py
[2024-09-16T21:11:05.924+0000] {processor.py:830} INFO - Processing file /opt/airflow/dags/dag.py for tasks to queue
[2024-09-16T21:11:05.927+0000] {logging_mixin.py:188} INFO - [2024-09-16T21:11:05.927+0000] {dagbag.py:545} INFO - Filling up the DagBag from /opt/airflow/dags/dag.py
[2024-09-16T21:11:07.146+0000] {logging_mixin.py:188} INFO - [2024-09-16T21:11:07.136+0000] {dagbag.py:355} ERROR - Failed to import: /opt/airflow/dags/dag.py
Traceback (most recent call last):
  File "/home/airflow/.local/lib/python3.12/site-packages/airflow/models/dagbag.py", line 351, in parse
    loader.exec_module(new_module)
  File "<frozen importlib._bootstrap_external>", line 995, in exec_module
  File "<frozen importlib._bootstrap>", line 488, in _call_with_frames_removed
  File "/opt/airflow/dags/dag.py", line 8, in <module>
    with DAG(
         ^^^^
  File "/home/airflow/.local/lib/python3.12/site-packages/airflow/models/dag.py", line 519, in __init__
    validate_key(dag_id)
  File "/home/airflow/.local/lib/python3.12/site-packages/airflow/utils/helpers.py", line 57, in validate_key
    raise AirflowException(
airflow.exceptions.AirflowException: The key '' has to be made of alphanumeric characters, dashes, dots and underscores exclusively
[2024-09-16T21:11:07.155+0000] {processor.py:842} WARNING - No viable dags retrieved from /opt/airflow/dags/dag.py
[2024-09-16T21:11:07.209+0000] {processor.py:183} INFO - Processing /opt/airflow/dags/dag.py took 1.303 seconds
[2024-09-16T21:11:37.349+0000] {processor.py:161} INFO - Started process (PID=211) to work on /opt/airflow/dags/dag.py
[2024-09-16T21:11:37.349+0000] {processor.py:830} INFO - Processing file /opt/airflow/dags/dag.py for tasks to queue
[2024-09-16T21:11:37.351+0000] {logging_mixin.py:188} INFO - [2024-09-16T21:11:37.350+0000] {dagbag.py:545} INFO - Filling up the DagBag from /opt/airflow/dags/dag.py
[2024-09-16T21:11:37.972+0000] {logging_mixin.py:188} INFO - [2024-09-16T21:11:37.970+0000] {dagbag.py:355} ERROR - Failed to import: /opt/airflow/dags/dag.py
Traceback (most recent call last):
  File "/home/airflow/.local/lib/python3.12/site-packages/airflow/models/dagbag.py", line 351, in parse
    loader.exec_module(new_module)
  File "<frozen importlib._bootstrap_external>", line 995, in exec_module
  File "<frozen importlib._bootstrap>", line 488, in _call_with_frames_removed
  File "/opt/airflow/dags/dag.py", line 8, in <module>
    with DAG(
         ^^^^
  File "/home/airflow/.local/lib/python3.12/site-packages/airflow/models/dag.py", line 519, in __init__
    validate_key(dag_id)
  File "/home/airflow/.local/lib/python3.12/site-packages/airflow/utils/helpers.py", line 57, in validate_key
    raise AirflowException(
airflow.exceptions.AirflowException: The key '' has to be made of alphanumeric characters, dashes, dots and underscores exclusively
[2024-09-16T21:11:37.973+0000] {processor.py:842} WARNING - No viable dags retrieved from /opt/airflow/dags/dag.py
[2024-09-16T21:11:37.997+0000] {processor.py:183} INFO - Processing /opt/airflow/dags/dag.py took 0.654 seconds
[2024-09-16T21:12:08.118+0000] {processor.py:161} INFO - Started process (PID=219) to work on /opt/airflow/dags/dag.py
[2024-09-16T21:12:08.118+0000] {processor.py:830} INFO - Processing file /opt/airflow/dags/dag.py for tasks to queue
[2024-09-16T21:12:08.120+0000] {logging_mixin.py:188} INFO - [2024-09-16T21:12:08.120+0000] {dagbag.py:545} INFO - Filling up the DagBag from /opt/airflow/dags/dag.py
[2024-09-16T21:12:08.616+0000] {logging_mixin.py:188} INFO - [2024-09-16T21:12:08.615+0000] {dagbag.py:355} ERROR - Failed to import: /opt/airflow/dags/dag.py
Traceback (most recent call last):
  File "/home/airflow/.local/lib/python3.12/site-packages/airflow/models/dagbag.py", line 351, in parse
    loader.exec_module(new_module)
  File "<frozen importlib._bootstrap_external>", line 995, in exec_module
  File "<frozen importlib._bootstrap>", line 488, in _call_with_frames_removed
  File "/opt/airflow/dags/dag.py", line 8, in <module>
    with DAG(
         ^^^^
  File "/home/airflow/.local/lib/python3.12/site-packages/airflow/models/dag.py", line 519, in __init__
    validate_key(dag_id)
  File "/home/airflow/.local/lib/python3.12/site-packages/airflow/utils/helpers.py", line 57, in validate_key
    raise AirflowException(
airflow.exceptions.AirflowException: The key '' has to be made of alphanumeric characters, dashes, dots and underscores exclusively
[2024-09-16T21:12:08.617+0000] {processor.py:842} WARNING - No viable dags retrieved from /opt/airflow/dags/dag.py
[2024-09-16T21:12:08.641+0000] {processor.py:183} INFO - Processing /opt/airflow/dags/dag.py took 0.528 seconds
[2024-09-16T21:12:38.763+0000] {processor.py:161} INFO - Started process (PID=228) to work on /opt/airflow/dags/dag.py
[2024-09-16T21:12:38.764+0000] {processor.py:830} INFO - Processing file /opt/airflow/dags/dag.py for tasks to queue
[2024-09-16T21:12:38.765+0000] {logging_mixin.py:188} INFO - [2024-09-16T21:12:38.765+0000] {dagbag.py:545} INFO - Filling up the DagBag from /opt/airflow/dags/dag.py
[2024-09-16T21:12:39.219+0000] {logging_mixin.py:188} INFO - [2024-09-16T21:12:39.218+0000] {dagbag.py:355} ERROR - Failed to import: /opt/airflow/dags/dag.py
Traceback (most recent call last):
  File "/home/airflow/.local/lib/python3.12/site-packages/airflow/models/dagbag.py", line 351, in parse
    loader.exec_module(new_module)
  File "<frozen importlib._bootstrap_external>", line 995, in exec_module
  File "<frozen importlib._bootstrap>", line 488, in _call_with_frames_removed
  File "/opt/airflow/dags/dag.py", line 8, in <module>
    with DAG(
         ^^^^
  File "/home/airflow/.local/lib/python3.12/site-packages/airflow/models/dag.py", line 519, in __init__
    validate_key(dag_id)
  File "/home/airflow/.local/lib/python3.12/site-packages/airflow/utils/helpers.py", line 57, in validate_key
    raise AirflowException(
airflow.exceptions.AirflowException: The key '' has to be made of alphanumeric characters, dashes, dots and underscores exclusively
[2024-09-16T21:12:39.220+0000] {processor.py:842} WARNING - No viable dags retrieved from /opt/airflow/dags/dag.py
[2024-09-16T21:12:39.245+0000] {processor.py:183} INFO - Processing /opt/airflow/dags/dag.py took 0.486 seconds
[2024-09-16T21:13:09.332+0000] {processor.py:161} INFO - Started process (PID=236) to work on /opt/airflow/dags/dag.py
[2024-09-16T21:13:09.333+0000] {processor.py:830} INFO - Processing file /opt/airflow/dags/dag.py for tasks to queue
[2024-09-16T21:13:09.334+0000] {logging_mixin.py:188} INFO - [2024-09-16T21:13:09.334+0000] {dagbag.py:545} INFO - Filling up the DagBag from /opt/airflow/dags/dag.py
[2024-09-16T21:13:09.674+0000] {logging_mixin.py:188} INFO - [2024-09-16T21:13:09.672+0000] {dagbag.py:355} ERROR - Failed to import: /opt/airflow/dags/dag.py
Traceback (most recent call last):
  File "/home/airflow/.local/lib/python3.12/site-packages/airflow/models/dagbag.py", line 351, in parse
    loader.exec_module(new_module)
  File "<frozen importlib._bootstrap_external>", line 995, in exec_module
  File "<frozen importlib._bootstrap>", line 488, in _call_with_frames_removed
  File "/opt/airflow/dags/dag.py", line 8, in <module>
    with DAG(
         ^^^^
  File "/home/airflow/.local/lib/python3.12/site-packages/airflow/models/dag.py", line 519, in __init__
    validate_key(dag_id)
  File "/home/airflow/.local/lib/python3.12/site-packages/airflow/utils/helpers.py", line 57, in validate_key
    raise AirflowException(
airflow.exceptions.AirflowException: The key '' has to be made of alphanumeric characters, dashes, dots and underscores exclusively
[2024-09-16T21:13:09.675+0000] {processor.py:842} WARNING - No viable dags retrieved from /opt/airflow/dags/dag.py
[2024-09-16T21:13:09.697+0000] {processor.py:183} INFO - Processing /opt/airflow/dags/dag.py took 0.370 seconds
[2024-09-16T21:13:39.820+0000] {processor.py:161} INFO - Started process (PID=244) to work on /opt/airflow/dags/dag.py
[2024-09-16T21:13:39.821+0000] {processor.py:830} INFO - Processing file /opt/airflow/dags/dag.py for tasks to queue
[2024-09-16T21:13:39.822+0000] {logging_mixin.py:188} INFO - [2024-09-16T21:13:39.822+0000] {dagbag.py:545} INFO - Filling up the DagBag from /opt/airflow/dags/dag.py
[2024-09-16T21:13:40.343+0000] {logging_mixin.py:188} INFO - [2024-09-16T21:13:40.342+0000] {dagbag.py:355} ERROR - Failed to import: /opt/airflow/dags/dag.py
Traceback (most recent call last):
  File "/home/airflow/.local/lib/python3.12/site-packages/airflow/models/dagbag.py", line 351, in parse
    loader.exec_module(new_module)
  File "<frozen importlib._bootstrap_external>", line 995, in exec_module
  File "<frozen importlib._bootstrap>", line 488, in _call_with_frames_removed
  File "/opt/airflow/dags/dag.py", line 8, in <module>
    with DAG(
         ^^^^
  File "/home/airflow/.local/lib/python3.12/site-packages/airflow/models/dag.py", line 519, in __init__
    validate_key(dag_id)
  File "/home/airflow/.local/lib/python3.12/site-packages/airflow/utils/helpers.py", line 57, in validate_key
    raise AirflowException(
airflow.exceptions.AirflowException: The key '' has to be made of alphanumeric characters, dashes, dots and underscores exclusively
[2024-09-16T21:13:40.344+0000] {processor.py:842} WARNING - No viable dags retrieved from /opt/airflow/dags/dag.py
[2024-09-16T21:13:40.364+0000] {processor.py:183} INFO - Processing /opt/airflow/dags/dag.py took 0.548 seconds
[2024-09-16T21:14:10.487+0000] {processor.py:161} INFO - Started process (PID=252) to work on /opt/airflow/dags/dag.py
[2024-09-16T21:14:10.487+0000] {processor.py:830} INFO - Processing file /opt/airflow/dags/dag.py for tasks to queue
[2024-09-16T21:14:10.489+0000] {logging_mixin.py:188} INFO - [2024-09-16T21:14:10.488+0000] {dagbag.py:545} INFO - Filling up the DagBag from /opt/airflow/dags/dag.py
[2024-09-16T21:14:10.978+0000] {logging_mixin.py:188} INFO - [2024-09-16T21:14:10.977+0000] {dagbag.py:355} ERROR - Failed to import: /opt/airflow/dags/dag.py
Traceback (most recent call last):
  File "/home/airflow/.local/lib/python3.12/site-packages/airflow/models/dagbag.py", line 351, in parse
    loader.exec_module(new_module)
  File "<frozen importlib._bootstrap_external>", line 995, in exec_module
  File "<frozen importlib._bootstrap>", line 488, in _call_with_frames_removed
  File "/opt/airflow/dags/dag.py", line 8, in <module>
    with DAG(
         ^^^^
  File "/home/airflow/.local/lib/python3.12/site-packages/airflow/models/dag.py", line 519, in __init__
    validate_key(dag_id)
  File "/home/airflow/.local/lib/python3.12/site-packages/airflow/utils/helpers.py", line 57, in validate_key
    raise AirflowException(
airflow.exceptions.AirflowException: The key '' has to be made of alphanumeric characters, dashes, dots and underscores exclusively
[2024-09-16T21:14:10.979+0000] {processor.py:842} WARNING - No viable dags retrieved from /opt/airflow/dags/dag.py
[2024-09-16T21:14:11.000+0000] {processor.py:183} INFO - Processing /opt/airflow/dags/dag.py took 0.520 seconds
[2024-09-16T21:14:41.105+0000] {processor.py:161} INFO - Started process (PID=260) to work on /opt/airflow/dags/dag.py
[2024-09-16T21:14:41.106+0000] {processor.py:830} INFO - Processing file /opt/airflow/dags/dag.py for tasks to queue
[2024-09-16T21:14:41.107+0000] {logging_mixin.py:188} INFO - [2024-09-16T21:14:41.107+0000] {dagbag.py:545} INFO - Filling up the DagBag from /opt/airflow/dags/dag.py
[2024-09-16T21:14:41.576+0000] {logging_mixin.py:188} INFO - [2024-09-16T21:14:41.574+0000] {dagbag.py:355} ERROR - Failed to import: /opt/airflow/dags/dag.py
Traceback (most recent call last):
  File "/home/airflow/.local/lib/python3.12/site-packages/airflow/models/dagbag.py", line 351, in parse
    loader.exec_module(new_module)
  File "<frozen importlib._bootstrap_external>", line 995, in exec_module
  File "<frozen importlib._bootstrap>", line 488, in _call_with_frames_removed
  File "/opt/airflow/dags/dag.py", line 8, in <module>
    with DAG(
         ^^^^
  File "/home/airflow/.local/lib/python3.12/site-packages/airflow/models/dag.py", line 519, in __init__
    validate_key(dag_id)
  File "/home/airflow/.local/lib/python3.12/site-packages/airflow/utils/helpers.py", line 57, in validate_key
    raise AirflowException(
airflow.exceptions.AirflowException: The key '' has to be made of alphanumeric characters, dashes, dots and underscores exclusively
[2024-09-16T21:14:41.577+0000] {processor.py:842} WARNING - No viable dags retrieved from /opt/airflow/dags/dag.py
[2024-09-16T21:14:41.601+0000] {processor.py:183} INFO - Processing /opt/airflow/dags/dag.py took 0.500 seconds
[2024-09-16T21:15:11.732+0000] {processor.py:161} INFO - Started process (PID=268) to work on /opt/airflow/dags/dag.py
[2024-09-16T21:15:11.733+0000] {processor.py:830} INFO - Processing file /opt/airflow/dags/dag.py for tasks to queue
[2024-09-16T21:15:11.734+0000] {logging_mixin.py:188} INFO - [2024-09-16T21:15:11.734+0000] {dagbag.py:545} INFO - Filling up the DagBag from /opt/airflow/dags/dag.py
[2024-09-16T21:15:12.257+0000] {logging_mixin.py:188} INFO - [2024-09-16T21:15:12.256+0000] {dagbag.py:355} ERROR - Failed to import: /opt/airflow/dags/dag.py
Traceback (most recent call last):
  File "/home/airflow/.local/lib/python3.12/site-packages/airflow/models/dagbag.py", line 351, in parse
    loader.exec_module(new_module)
  File "<frozen importlib._bootstrap_external>", line 995, in exec_module
  File "<frozen importlib._bootstrap>", line 488, in _call_with_frames_removed
  File "/opt/airflow/dags/dag.py", line 8, in <module>
    with DAG(
         ^^^^
  File "/home/airflow/.local/lib/python3.12/site-packages/airflow/models/dag.py", line 519, in __init__
    validate_key(dag_id)
  File "/home/airflow/.local/lib/python3.12/site-packages/airflow/utils/helpers.py", line 57, in validate_key
    raise AirflowException(
airflow.exceptions.AirflowException: The key '' has to be made of alphanumeric characters, dashes, dots and underscores exclusively
[2024-09-16T21:15:12.258+0000] {processor.py:842} WARNING - No viable dags retrieved from /opt/airflow/dags/dag.py
[2024-09-16T21:15:12.277+0000] {processor.py:183} INFO - Processing /opt/airflow/dags/dag.py took 0.550 seconds
[2024-09-16T21:15:42.323+0000] {processor.py:161} INFO - Started process (PID=276) to work on /opt/airflow/dags/dag.py
[2024-09-16T21:15:42.324+0000] {processor.py:830} INFO - Processing file /opt/airflow/dags/dag.py for tasks to queue
[2024-09-16T21:15:42.325+0000] {logging_mixin.py:188} INFO - [2024-09-16T21:15:42.325+0000] {dagbag.py:545} INFO - Filling up the DagBag from /opt/airflow/dags/dag.py
[2024-09-16T21:15:42.891+0000] {logging_mixin.py:188} INFO - [2024-09-16T21:15:42.890+0000] {dagbag.py:355} ERROR - Failed to import: /opt/airflow/dags/dag.py
Traceback (most recent call last):
  File "/home/airflow/.local/lib/python3.12/site-packages/airflow/models/dagbag.py", line 351, in parse
    loader.exec_module(new_module)
  File "<frozen importlib._bootstrap_external>", line 995, in exec_module
  File "<frozen importlib._bootstrap>", line 488, in _call_with_frames_removed
  File "/opt/airflow/dags/dag.py", line 8, in <module>
    with DAG(
         ^^^^
  File "/home/airflow/.local/lib/python3.12/site-packages/airflow/models/dag.py", line 519, in __init__
    validate_key(dag_id)
  File "/home/airflow/.local/lib/python3.12/site-packages/airflow/utils/helpers.py", line 57, in validate_key
    raise AirflowException(
airflow.exceptions.AirflowException: The key '' has to be made of alphanumeric characters, dashes, dots and underscores exclusively
[2024-09-16T21:15:42.892+0000] {processor.py:842} WARNING - No viable dags retrieved from /opt/airflow/dags/dag.py
[2024-09-16T21:15:42.912+0000] {processor.py:183} INFO - Processing /opt/airflow/dags/dag.py took 0.593 seconds
[2024-09-16T21:16:13.031+0000] {processor.py:161} INFO - Started process (PID=284) to work on /opt/airflow/dags/dag.py
[2024-09-16T21:16:13.032+0000] {processor.py:830} INFO - Processing file /opt/airflow/dags/dag.py for tasks to queue
[2024-09-16T21:16:13.034+0000] {logging_mixin.py:188} INFO - [2024-09-16T21:16:13.034+0000] {dagbag.py:545} INFO - Filling up the DagBag from /opt/airflow/dags/dag.py
[2024-09-16T21:16:13.395+0000] {logging_mixin.py:188} INFO - [2024-09-16T21:16:13.393+0000] {dagbag.py:355} ERROR - Failed to import: /opt/airflow/dags/dag.py
Traceback (most recent call last):
  File "/home/airflow/.local/lib/python3.12/site-packages/airflow/models/dagbag.py", line 351, in parse
    loader.exec_module(new_module)
  File "<frozen importlib._bootstrap_external>", line 995, in exec_module
  File "<frozen importlib._bootstrap>", line 488, in _call_with_frames_removed
  File "/opt/airflow/dags/dag.py", line 8, in <module>
    with DAG(
         ^^^^
  File "/home/airflow/.local/lib/python3.12/site-packages/airflow/models/dag.py", line 519, in __init__
    validate_key(dag_id)
  File "/home/airflow/.local/lib/python3.12/site-packages/airflow/utils/helpers.py", line 57, in validate_key
    raise AirflowException(
airflow.exceptions.AirflowException: The key '' has to be made of alphanumeric characters, dashes, dots and underscores exclusively
[2024-09-16T21:16:13.395+0000] {processor.py:842} WARNING - No viable dags retrieved from /opt/airflow/dags/dag.py
[2024-09-16T21:16:13.420+0000] {processor.py:183} INFO - Processing /opt/airflow/dags/dag.py took 0.395 seconds
[2024-09-16T21:16:43.548+0000] {processor.py:161} INFO - Started process (PID=292) to work on /opt/airflow/dags/dag.py
[2024-09-16T21:16:43.549+0000] {processor.py:830} INFO - Processing file /opt/airflow/dags/dag.py for tasks to queue
[2024-09-16T21:16:43.553+0000] {logging_mixin.py:188} INFO - [2024-09-16T21:16:43.552+0000] {dagbag.py:545} INFO - Filling up the DagBag from /opt/airflow/dags/dag.py
[2024-09-16T21:16:44.683+0000] {logging_mixin.py:188} INFO - [2024-09-16T21:16:44.680+0000] {dagbag.py:355} ERROR - Failed to import: /opt/airflow/dags/dag.py
Traceback (most recent call last):
  File "/home/airflow/.local/lib/python3.12/site-packages/airflow/models/dagbag.py", line 351, in parse
    loader.exec_module(new_module)
  File "<frozen importlib._bootstrap_external>", line 995, in exec_module
  File "<frozen importlib._bootstrap>", line 488, in _call_with_frames_removed
  File "/opt/airflow/dags/dag.py", line 8, in <module>
    with DAG(
         ^^^^
  File "/home/airflow/.local/lib/python3.12/site-packages/airflow/models/dag.py", line 519, in __init__
    validate_key(dag_id)
  File "/home/airflow/.local/lib/python3.12/site-packages/airflow/utils/helpers.py", line 57, in validate_key
    raise AirflowException(
airflow.exceptions.AirflowException: The key '' has to be made of alphanumeric characters, dashes, dots and underscores exclusively
[2024-09-16T21:16:44.684+0000] {processor.py:842} WARNING - No viable dags retrieved from /opt/airflow/dags/dag.py
[2024-09-16T21:16:44.724+0000] {processor.py:183} INFO - Processing /opt/airflow/dags/dag.py took 1.190 seconds
[2024-09-16T21:17:14.859+0000] {processor.py:161} INFO - Started process (PID=300) to work on /opt/airflow/dags/dag.py
[2024-09-16T21:17:14.860+0000] {processor.py:830} INFO - Processing file /opt/airflow/dags/dag.py for tasks to queue
[2024-09-16T21:17:14.861+0000] {logging_mixin.py:188} INFO - [2024-09-16T21:17:14.861+0000] {dagbag.py:545} INFO - Filling up the DagBag from /opt/airflow/dags/dag.py
[2024-09-16T21:17:15.449+0000] {logging_mixin.py:188} INFO - [2024-09-16T21:17:15.447+0000] {dagbag.py:355} ERROR - Failed to import: /opt/airflow/dags/dag.py
Traceback (most recent call last):
  File "/home/airflow/.local/lib/python3.12/site-packages/airflow/models/dagbag.py", line 351, in parse
    loader.exec_module(new_module)
  File "<frozen importlib._bootstrap_external>", line 995, in exec_module
  File "<frozen importlib._bootstrap>", line 488, in _call_with_frames_removed
  File "/opt/airflow/dags/dag.py", line 8, in <module>
    with DAG(
         ^^^^
  File "/home/airflow/.local/lib/python3.12/site-packages/airflow/models/dag.py", line 519, in __init__
    validate_key(dag_id)
  File "/home/airflow/.local/lib/python3.12/site-packages/airflow/utils/helpers.py", line 57, in validate_key
    raise AirflowException(
airflow.exceptions.AirflowException: The key '' has to be made of alphanumeric characters, dashes, dots and underscores exclusively
[2024-09-16T21:17:15.449+0000] {processor.py:842} WARNING - No viable dags retrieved from /opt/airflow/dags/dag.py
[2024-09-16T21:17:15.475+0000] {processor.py:183} INFO - Processing /opt/airflow/dags/dag.py took 0.620 seconds
[2024-09-16T21:17:45.602+0000] {processor.py:161} INFO - Started process (PID=308) to work on /opt/airflow/dags/dag.py
[2024-09-16T21:17:45.603+0000] {processor.py:830} INFO - Processing file /opt/airflow/dags/dag.py for tasks to queue
[2024-09-16T21:17:45.605+0000] {logging_mixin.py:188} INFO - [2024-09-16T21:17:45.605+0000] {dagbag.py:545} INFO - Filling up the DagBag from /opt/airflow/dags/dag.py
[2024-09-16T21:17:46.221+0000] {logging_mixin.py:188} INFO - [2024-09-16T21:17:46.219+0000] {dagbag.py:355} ERROR - Failed to import: /opt/airflow/dags/dag.py
Traceback (most recent call last):
  File "/home/airflow/.local/lib/python3.12/site-packages/airflow/models/dagbag.py", line 351, in parse
    loader.exec_module(new_module)
  File "<frozen importlib._bootstrap_external>", line 995, in exec_module
  File "<frozen importlib._bootstrap>", line 488, in _call_with_frames_removed
  File "/opt/airflow/dags/dag.py", line 8, in <module>
    with DAG(
         ^^^^
  File "/home/airflow/.local/lib/python3.12/site-packages/airflow/models/dag.py", line 519, in __init__
    validate_key(dag_id)
  File "/home/airflow/.local/lib/python3.12/site-packages/airflow/utils/helpers.py", line 57, in validate_key
    raise AirflowException(
airflow.exceptions.AirflowException: The key '' has to be made of alphanumeric characters, dashes, dots and underscores exclusively
[2024-09-16T21:17:46.222+0000] {processor.py:842} WARNING - No viable dags retrieved from /opt/airflow/dags/dag.py
[2024-09-16T21:17:46.248+0000] {processor.py:183} INFO - Processing /opt/airflow/dags/dag.py took 0.652 seconds
[2024-09-16T21:18:16.365+0000] {processor.py:161} INFO - Started process (PID=317) to work on /opt/airflow/dags/dag.py
[2024-09-16T21:18:16.365+0000] {processor.py:830} INFO - Processing file /opt/airflow/dags/dag.py for tasks to queue
[2024-09-16T21:18:16.367+0000] {logging_mixin.py:188} INFO - [2024-09-16T21:18:16.367+0000] {dagbag.py:545} INFO - Filling up the DagBag from /opt/airflow/dags/dag.py
[2024-09-16T21:18:16.881+0000] {logging_mixin.py:188} INFO - [2024-09-16T21:18:16.879+0000] {dagbag.py:355} ERROR - Failed to import: /opt/airflow/dags/dag.py
Traceback (most recent call last):
  File "/home/airflow/.local/lib/python3.12/site-packages/airflow/models/dagbag.py", line 351, in parse
    loader.exec_module(new_module)
  File "<frozen importlib._bootstrap_external>", line 995, in exec_module
  File "<frozen importlib._bootstrap>", line 488, in _call_with_frames_removed
  File "/opt/airflow/dags/dag.py", line 8, in <module>
    with DAG(
         ^^^^
  File "/home/airflow/.local/lib/python3.12/site-packages/airflow/models/dag.py", line 519, in __init__
    validate_key(dag_id)
  File "/home/airflow/.local/lib/python3.12/site-packages/airflow/utils/helpers.py", line 57, in validate_key
    raise AirflowException(
airflow.exceptions.AirflowException: The key '' has to be made of alphanumeric characters, dashes, dots and underscores exclusively
[2024-09-16T21:18:16.881+0000] {processor.py:842} WARNING - No viable dags retrieved from /opt/airflow/dags/dag.py
[2024-09-16T21:18:16.905+0000] {processor.py:183} INFO - Processing /opt/airflow/dags/dag.py took 0.544 seconds
[2024-09-16T21:18:47.026+0000] {processor.py:161} INFO - Started process (PID=326) to work on /opt/airflow/dags/dag.py
[2024-09-16T21:18:47.026+0000] {processor.py:830} INFO - Processing file /opt/airflow/dags/dag.py for tasks to queue
[2024-09-16T21:18:47.028+0000] {logging_mixin.py:188} INFO - [2024-09-16T21:18:47.027+0000] {dagbag.py:545} INFO - Filling up the DagBag from /opt/airflow/dags/dag.py
[2024-09-16T21:18:47.526+0000] {logging_mixin.py:188} INFO - [2024-09-16T21:18:47.524+0000] {dagbag.py:355} ERROR - Failed to import: /opt/airflow/dags/dag.py
Traceback (most recent call last):
  File "/home/airflow/.local/lib/python3.12/site-packages/airflow/models/dagbag.py", line 351, in parse
    loader.exec_module(new_module)
  File "<frozen importlib._bootstrap_external>", line 995, in exec_module
  File "<frozen importlib._bootstrap>", line 488, in _call_with_frames_removed
  File "/opt/airflow/dags/dag.py", line 8, in <module>
    with DAG(
         ^^^^
  File "/home/airflow/.local/lib/python3.12/site-packages/airflow/models/dag.py", line 519, in __init__
    validate_key(dag_id)
  File "/home/airflow/.local/lib/python3.12/site-packages/airflow/utils/helpers.py", line 57, in validate_key
    raise AirflowException(
airflow.exceptions.AirflowException: The key '' has to be made of alphanumeric characters, dashes, dots and underscores exclusively
[2024-09-16T21:18:47.526+0000] {processor.py:842} WARNING - No viable dags retrieved from /opt/airflow/dags/dag.py
[2024-09-16T21:18:47.544+0000] {processor.py:183} INFO - Processing /opt/airflow/dags/dag.py took 0.523 seconds
[2024-09-16T21:19:17.651+0000] {processor.py:161} INFO - Started process (PID=335) to work on /opt/airflow/dags/dag.py
[2024-09-16T21:19:17.652+0000] {processor.py:830} INFO - Processing file /opt/airflow/dags/dag.py for tasks to queue
[2024-09-16T21:19:17.653+0000] {logging_mixin.py:188} INFO - [2024-09-16T21:19:17.653+0000] {dagbag.py:545} INFO - Filling up the DagBag from /opt/airflow/dags/dag.py
[2024-09-16T21:19:18.053+0000] {logging_mixin.py:188} INFO - [2024-09-16T21:19:18.051+0000] {dagbag.py:355} ERROR - Failed to import: /opt/airflow/dags/dag.py
Traceback (most recent call last):
  File "/home/airflow/.local/lib/python3.12/site-packages/airflow/models/dagbag.py", line 351, in parse
    loader.exec_module(new_module)
  File "<frozen importlib._bootstrap_external>", line 995, in exec_module
  File "<frozen importlib._bootstrap>", line 488, in _call_with_frames_removed
  File "/opt/airflow/dags/dag.py", line 8, in <module>
    with DAG(
         ^^^^
  File "/home/airflow/.local/lib/python3.12/site-packages/airflow/models/dag.py", line 519, in __init__
    validate_key(dag_id)
  File "/home/airflow/.local/lib/python3.12/site-packages/airflow/utils/helpers.py", line 57, in validate_key
    raise AirflowException(
airflow.exceptions.AirflowException: The key '' has to be made of alphanumeric characters, dashes, dots and underscores exclusively
[2024-09-16T21:19:18.053+0000] {processor.py:842} WARNING - No viable dags retrieved from /opt/airflow/dags/dag.py
[2024-09-16T21:19:18.089+0000] {processor.py:183} INFO - Processing /opt/airflow/dags/dag.py took 0.443 seconds
[2024-09-16T21:19:48.205+0000] {processor.py:161} INFO - Started process (PID=344) to work on /opt/airflow/dags/dag.py
[2024-09-16T21:19:48.205+0000] {processor.py:830} INFO - Processing file /opt/airflow/dags/dag.py for tasks to queue
[2024-09-16T21:19:48.207+0000] {logging_mixin.py:188} INFO - [2024-09-16T21:19:48.207+0000] {dagbag.py:545} INFO - Filling up the DagBag from /opt/airflow/dags/dag.py
[2024-09-16T21:19:48.726+0000] {logging_mixin.py:188} INFO - [2024-09-16T21:19:48.724+0000] {dagbag.py:355} ERROR - Failed to import: /opt/airflow/dags/dag.py
Traceback (most recent call last):
  File "/home/airflow/.local/lib/python3.12/site-packages/airflow/models/dagbag.py", line 351, in parse
    loader.exec_module(new_module)
  File "<frozen importlib._bootstrap_external>", line 995, in exec_module
  File "<frozen importlib._bootstrap>", line 488, in _call_with_frames_removed
  File "/opt/airflow/dags/dag.py", line 8, in <module>
    with DAG(
         ^^^^
  File "/home/airflow/.local/lib/python3.12/site-packages/airflow/models/dag.py", line 519, in __init__
    validate_key(dag_id)
  File "/home/airflow/.local/lib/python3.12/site-packages/airflow/utils/helpers.py", line 57, in validate_key
    raise AirflowException(
airflow.exceptions.AirflowException: The key '' has to be made of alphanumeric characters, dashes, dots and underscores exclusively
[2024-09-16T21:19:48.727+0000] {processor.py:842} WARNING - No viable dags retrieved from /opt/airflow/dags/dag.py
[2024-09-16T21:19:48.753+0000] {processor.py:183} INFO - Processing /opt/airflow/dags/dag.py took 0.553 seconds
[2024-09-16T21:20:18.867+0000] {processor.py:161} INFO - Started process (PID=353) to work on /opt/airflow/dags/dag.py
[2024-09-16T21:20:18.867+0000] {processor.py:830} INFO - Processing file /opt/airflow/dags/dag.py for tasks to queue
[2024-09-16T21:20:18.869+0000] {logging_mixin.py:188} INFO - [2024-09-16T21:20:18.868+0000] {dagbag.py:545} INFO - Filling up the DagBag from /opt/airflow/dags/dag.py
[2024-09-16T21:20:19.383+0000] {logging_mixin.py:188} INFO - [2024-09-16T21:20:19.381+0000] {dagbag.py:355} ERROR - Failed to import: /opt/airflow/dags/dag.py
Traceback (most recent call last):
  File "/home/airflow/.local/lib/python3.12/site-packages/airflow/models/dagbag.py", line 351, in parse
    loader.exec_module(new_module)
  File "<frozen importlib._bootstrap_external>", line 995, in exec_module
  File "<frozen importlib._bootstrap>", line 488, in _call_with_frames_removed
  File "/opt/airflow/dags/dag.py", line 8, in <module>
    with DAG(
         ^^^^
  File "/home/airflow/.local/lib/python3.12/site-packages/airflow/models/dag.py", line 519, in __init__
    validate_key(dag_id)
  File "/home/airflow/.local/lib/python3.12/site-packages/airflow/utils/helpers.py", line 57, in validate_key
    raise AirflowException(
airflow.exceptions.AirflowException: The key '' has to be made of alphanumeric characters, dashes, dots and underscores exclusively
[2024-09-16T21:20:19.384+0000] {processor.py:842} WARNING - No viable dags retrieved from /opt/airflow/dags/dag.py
[2024-09-16T21:20:19.415+0000] {processor.py:183} INFO - Processing /opt/airflow/dags/dag.py took 0.553 seconds
[2024-09-16T21:20:49.542+0000] {processor.py:161} INFO - Started process (PID=362) to work on /opt/airflow/dags/dag.py
[2024-09-16T21:20:49.543+0000] {processor.py:830} INFO - Processing file /opt/airflow/dags/dag.py for tasks to queue
[2024-09-16T21:20:49.545+0000] {logging_mixin.py:188} INFO - [2024-09-16T21:20:49.544+0000] {dagbag.py:545} INFO - Filling up the DagBag from /opt/airflow/dags/dag.py
[2024-09-16T21:20:50.174+0000] {logging_mixin.py:188} INFO - [2024-09-16T21:20:50.171+0000] {dagbag.py:355} ERROR - Failed to import: /opt/airflow/dags/dag.py
Traceback (most recent call last):
  File "/home/airflow/.local/lib/python3.12/site-packages/airflow/models/dagbag.py", line 351, in parse
    loader.exec_module(new_module)
  File "<frozen importlib._bootstrap_external>", line 995, in exec_module
  File "<frozen importlib._bootstrap>", line 488, in _call_with_frames_removed
  File "/opt/airflow/dags/dag.py", line 8, in <module>
    with DAG(
         ^^^^
  File "/home/airflow/.local/lib/python3.12/site-packages/airflow/models/dag.py", line 519, in __init__
    validate_key(dag_id)
  File "/home/airflow/.local/lib/python3.12/site-packages/airflow/utils/helpers.py", line 57, in validate_key
    raise AirflowException(
airflow.exceptions.AirflowException: The key '' has to be made of alphanumeric characters, dashes, dots and underscores exclusively
[2024-09-16T21:20:50.175+0000] {processor.py:842} WARNING - No viable dags retrieved from /opt/airflow/dags/dag.py
[2024-09-16T21:20:50.202+0000] {processor.py:183} INFO - Processing /opt/airflow/dags/dag.py took 0.666 seconds
[2024-09-16T21:21:20.320+0000] {processor.py:161} INFO - Started process (PID=371) to work on /opt/airflow/dags/dag.py
[2024-09-16T21:21:20.321+0000] {processor.py:830} INFO - Processing file /opt/airflow/dags/dag.py for tasks to queue
[2024-09-16T21:21:20.322+0000] {logging_mixin.py:188} INFO - [2024-09-16T21:21:20.322+0000] {dagbag.py:545} INFO - Filling up the DagBag from /opt/airflow/dags/dag.py
[2024-09-16T21:21:20.899+0000] {logging_mixin.py:188} INFO - [2024-09-16T21:21:20.897+0000] {dagbag.py:355} ERROR - Failed to import: /opt/airflow/dags/dag.py
Traceback (most recent call last):
  File "/home/airflow/.local/lib/python3.12/site-packages/airflow/models/dagbag.py", line 351, in parse
    loader.exec_module(new_module)
  File "<frozen importlib._bootstrap_external>", line 995, in exec_module
  File "<frozen importlib._bootstrap>", line 488, in _call_with_frames_removed
  File "/opt/airflow/dags/dag.py", line 8, in <module>
    with DAG(
         ^^^^
  File "/home/airflow/.local/lib/python3.12/site-packages/airflow/models/dag.py", line 519, in __init__
    validate_key(dag_id)
  File "/home/airflow/.local/lib/python3.12/site-packages/airflow/utils/helpers.py", line 57, in validate_key
    raise AirflowException(
airflow.exceptions.AirflowException: The key '' has to be made of alphanumeric characters, dashes, dots and underscores exclusively
[2024-09-16T21:21:20.900+0000] {processor.py:842} WARNING - No viable dags retrieved from /opt/airflow/dags/dag.py
[2024-09-16T21:21:20.922+0000] {processor.py:183} INFO - Processing /opt/airflow/dags/dag.py took 0.606 seconds
[2024-09-16T21:21:51.063+0000] {processor.py:161} INFO - Started process (PID=380) to work on /opt/airflow/dags/dag.py
[2024-09-16T21:21:51.068+0000] {processor.py:830} INFO - Processing file /opt/airflow/dags/dag.py for tasks to queue
[2024-09-16T21:21:51.070+0000] {logging_mixin.py:188} INFO - [2024-09-16T21:21:51.070+0000] {dagbag.py:545} INFO - Filling up the DagBag from /opt/airflow/dags/dag.py
[2024-09-16T21:21:52.559+0000] {logging_mixin.py:188} INFO - [2024-09-16T21:21:52.556+0000] {dagbag.py:355} ERROR - Failed to import: /opt/airflow/dags/dag.py
Traceback (most recent call last):
  File "/home/airflow/.local/lib/python3.12/site-packages/airflow/models/dagbag.py", line 351, in parse
    loader.exec_module(new_module)
  File "<frozen importlib._bootstrap_external>", line 995, in exec_module
  File "<frozen importlib._bootstrap>", line 488, in _call_with_frames_removed
  File "/opt/airflow/dags/dag.py", line 8, in <module>
    with DAG(
         ^^^^
  File "/home/airflow/.local/lib/python3.12/site-packages/airflow/models/dag.py", line 519, in __init__
    validate_key(dag_id)
  File "/home/airflow/.local/lib/python3.12/site-packages/airflow/utils/helpers.py", line 57, in validate_key
    raise AirflowException(
airflow.exceptions.AirflowException: The key '' has to be made of alphanumeric characters, dashes, dots and underscores exclusively
[2024-09-16T21:21:52.560+0000] {processor.py:842} WARNING - No viable dags retrieved from /opt/airflow/dags/dag.py
[2024-09-16T21:21:52.607+0000] {processor.py:183} INFO - Processing /opt/airflow/dags/dag.py took 1.560 seconds
[2024-09-16T21:22:22.748+0000] {processor.py:161} INFO - Started process (PID=388) to work on /opt/airflow/dags/dag.py
[2024-09-16T21:22:22.749+0000] {processor.py:830} INFO - Processing file /opt/airflow/dags/dag.py for tasks to queue
[2024-09-16T21:22:22.750+0000] {logging_mixin.py:188} INFO - [2024-09-16T21:22:22.750+0000] {dagbag.py:545} INFO - Filling up the DagBag from /opt/airflow/dags/dag.py
[2024-09-16T21:22:23.075+0000] {logging_mixin.py:188} INFO - [2024-09-16T21:22:23.073+0000] {dagbag.py:355} ERROR - Failed to import: /opt/airflow/dags/dag.py
Traceback (most recent call last):
  File "/home/airflow/.local/lib/python3.12/site-packages/airflow/models/dagbag.py", line 351, in parse
    loader.exec_module(new_module)
  File "<frozen importlib._bootstrap_external>", line 995, in exec_module
  File "<frozen importlib._bootstrap>", line 488, in _call_with_frames_removed
  File "/opt/airflow/dags/dag.py", line 8, in <module>
    with DAG(
         ^^^^
  File "/home/airflow/.local/lib/python3.12/site-packages/airflow/models/dag.py", line 519, in __init__
    validate_key(dag_id)
  File "/home/airflow/.local/lib/python3.12/site-packages/airflow/utils/helpers.py", line 57, in validate_key
    raise AirflowException(
airflow.exceptions.AirflowException: The key '' has to be made of alphanumeric characters, dashes, dots and underscores exclusively
[2024-09-16T21:22:23.076+0000] {processor.py:842} WARNING - No viable dags retrieved from /opt/airflow/dags/dag.py
[2024-09-16T21:22:23.096+0000] {processor.py:183} INFO - Processing /opt/airflow/dags/dag.py took 0.352 seconds
[2024-09-16T21:22:53.209+0000] {processor.py:161} INFO - Started process (PID=396) to work on /opt/airflow/dags/dag.py
[2024-09-16T21:22:53.209+0000] {processor.py:830} INFO - Processing file /opt/airflow/dags/dag.py for tasks to queue
[2024-09-16T21:22:53.211+0000] {logging_mixin.py:188} INFO - [2024-09-16T21:22:53.211+0000] {dagbag.py:545} INFO - Filling up the DagBag from /opt/airflow/dags/dag.py
[2024-09-16T21:22:53.715+0000] {logging_mixin.py:188} INFO - [2024-09-16T21:22:53.714+0000] {dagbag.py:355} ERROR - Failed to import: /opt/airflow/dags/dag.py
Traceback (most recent call last):
  File "/home/airflow/.local/lib/python3.12/site-packages/airflow/models/dagbag.py", line 351, in parse
    loader.exec_module(new_module)
  File "<frozen importlib._bootstrap_external>", line 995, in exec_module
  File "<frozen importlib._bootstrap>", line 488, in _call_with_frames_removed
  File "/opt/airflow/dags/dag.py", line 8, in <module>
    with DAG(
         ^^^^
  File "/home/airflow/.local/lib/python3.12/site-packages/airflow/models/dag.py", line 519, in __init__
    validate_key(dag_id)
  File "/home/airflow/.local/lib/python3.12/site-packages/airflow/utils/helpers.py", line 57, in validate_key
    raise AirflowException(
airflow.exceptions.AirflowException: The key '' has to be made of alphanumeric characters, dashes, dots and underscores exclusively
[2024-09-16T21:22:53.716+0000] {processor.py:842} WARNING - No viable dags retrieved from /opt/airflow/dags/dag.py
[2024-09-16T21:22:53.735+0000] {processor.py:183} INFO - Processing /opt/airflow/dags/dag.py took 0.531 seconds
[2024-09-16T21:23:23.855+0000] {processor.py:161} INFO - Started process (PID=404) to work on /opt/airflow/dags/dag.py
[2024-09-16T21:23:23.856+0000] {processor.py:830} INFO - Processing file /opt/airflow/dags/dag.py for tasks to queue
[2024-09-16T21:23:23.857+0000] {logging_mixin.py:188} INFO - [2024-09-16T21:23:23.857+0000] {dagbag.py:545} INFO - Filling up the DagBag from /opt/airflow/dags/dag.py
[2024-09-16T21:23:24.337+0000] {logging_mixin.py:188} INFO - [2024-09-16T21:23:24.336+0000] {dagbag.py:355} ERROR - Failed to import: /opt/airflow/dags/dag.py
Traceback (most recent call last):
  File "/home/airflow/.local/lib/python3.12/site-packages/airflow/models/dagbag.py", line 351, in parse
    loader.exec_module(new_module)
  File "<frozen importlib._bootstrap_external>", line 995, in exec_module
  File "<frozen importlib._bootstrap>", line 488, in _call_with_frames_removed
  File "/opt/airflow/dags/dag.py", line 8, in <module>
    with DAG(
         ^^^^
  File "/home/airflow/.local/lib/python3.12/site-packages/airflow/models/dag.py", line 519, in __init__
    validate_key(dag_id)
  File "/home/airflow/.local/lib/python3.12/site-packages/airflow/utils/helpers.py", line 57, in validate_key
    raise AirflowException(
airflow.exceptions.AirflowException: The key '' has to be made of alphanumeric characters, dashes, dots and underscores exclusively
[2024-09-16T21:23:24.338+0000] {processor.py:842} WARNING - No viable dags retrieved from /opt/airflow/dags/dag.py
[2024-09-16T21:23:24.358+0000] {processor.py:183} INFO - Processing /opt/airflow/dags/dag.py took 0.507 seconds
[2024-09-16T21:23:54.409+0000] {processor.py:161} INFO - Started process (PID=412) to work on /opt/airflow/dags/dag.py
[2024-09-16T21:23:54.410+0000] {processor.py:830} INFO - Processing file /opt/airflow/dags/dag.py for tasks to queue
[2024-09-16T21:23:54.411+0000] {logging_mixin.py:188} INFO - [2024-09-16T21:23:54.411+0000] {dagbag.py:545} INFO - Filling up the DagBag from /opt/airflow/dags/dag.py
[2024-09-16T21:23:54.866+0000] {logging_mixin.py:188} INFO - [2024-09-16T21:23:54.864+0000] {dagbag.py:355} ERROR - Failed to import: /opt/airflow/dags/dag.py
Traceback (most recent call last):
  File "/home/airflow/.local/lib/python3.12/site-packages/airflow/models/dagbag.py", line 351, in parse
    loader.exec_module(new_module)
  File "<frozen importlib._bootstrap_external>", line 995, in exec_module
  File "<frozen importlib._bootstrap>", line 488, in _call_with_frames_removed
  File "/opt/airflow/dags/dag.py", line 8, in <module>
    with DAG(
         ^^^^
  File "/home/airflow/.local/lib/python3.12/site-packages/airflow/models/dag.py", line 519, in __init__
    validate_key(dag_id)
  File "/home/airflow/.local/lib/python3.12/site-packages/airflow/utils/helpers.py", line 57, in validate_key
    raise AirflowException(
airflow.exceptions.AirflowException: The key '' has to be made of alphanumeric characters, dashes, dots and underscores exclusively
[2024-09-16T21:23:54.866+0000] {processor.py:842} WARNING - No viable dags retrieved from /opt/airflow/dags/dag.py
[2024-09-16T21:23:54.886+0000] {processor.py:183} INFO - Processing /opt/airflow/dags/dag.py took 0.481 seconds
[2024-09-16T21:24:25.002+0000] {processor.py:161} INFO - Started process (PID=421) to work on /opt/airflow/dags/dag.py
[2024-09-16T21:24:25.002+0000] {processor.py:830} INFO - Processing file /opt/airflow/dags/dag.py for tasks to queue
[2024-09-16T21:24:25.004+0000] {logging_mixin.py:188} INFO - [2024-09-16T21:24:25.003+0000] {dagbag.py:545} INFO - Filling up the DagBag from /opt/airflow/dags/dag.py
[2024-09-16T21:24:25.457+0000] {logging_mixin.py:188} INFO - [2024-09-16T21:24:25.455+0000] {dagbag.py:355} ERROR - Failed to import: /opt/airflow/dags/dag.py
Traceback (most recent call last):
  File "/home/airflow/.local/lib/python3.12/site-packages/airflow/models/dagbag.py", line 351, in parse
    loader.exec_module(new_module)
  File "<frozen importlib._bootstrap_external>", line 995, in exec_module
  File "<frozen importlib._bootstrap>", line 488, in _call_with_frames_removed
  File "/opt/airflow/dags/dag.py", line 8, in <module>
    with DAG(
         ^^^^
  File "/home/airflow/.local/lib/python3.12/site-packages/airflow/models/dag.py", line 519, in __init__
    validate_key(dag_id)
  File "/home/airflow/.local/lib/python3.12/site-packages/airflow/utils/helpers.py", line 57, in validate_key
    raise AirflowException(
airflow.exceptions.AirflowException: The key '' has to be made of alphanumeric characters, dashes, dots and underscores exclusively
[2024-09-16T21:24:25.457+0000] {processor.py:842} WARNING - No viable dags retrieved from /opt/airflow/dags/dag.py
[2024-09-16T21:24:25.478+0000] {processor.py:183} INFO - Processing /opt/airflow/dags/dag.py took 0.480 seconds
[2024-09-16T21:24:55.593+0000] {processor.py:161} INFO - Started process (PID=430) to work on /opt/airflow/dags/dag.py
[2024-09-16T21:24:55.594+0000] {processor.py:830} INFO - Processing file /opt/airflow/dags/dag.py for tasks to queue
[2024-09-16T21:24:55.595+0000] {logging_mixin.py:188} INFO - [2024-09-16T21:24:55.595+0000] {dagbag.py:545} INFO - Filling up the DagBag from /opt/airflow/dags/dag.py
[2024-09-16T21:24:56.032+0000] {logging_mixin.py:188} INFO - [2024-09-16T21:24:56.031+0000] {dagbag.py:355} ERROR - Failed to import: /opt/airflow/dags/dag.py
Traceback (most recent call last):
  File "/home/airflow/.local/lib/python3.12/site-packages/airflow/models/dagbag.py", line 351, in parse
    loader.exec_module(new_module)
  File "<frozen importlib._bootstrap_external>", line 995, in exec_module
  File "<frozen importlib._bootstrap>", line 488, in _call_with_frames_removed
  File "/opt/airflow/dags/dag.py", line 8, in <module>
    with DAG(
         ^^^^
  File "/home/airflow/.local/lib/python3.12/site-packages/airflow/models/dag.py", line 519, in __init__
    validate_key(dag_id)
  File "/home/airflow/.local/lib/python3.12/site-packages/airflow/utils/helpers.py", line 57, in validate_key
    raise AirflowException(
airflow.exceptions.AirflowException: The key '' has to be made of alphanumeric characters, dashes, dots and underscores exclusively
[2024-09-16T21:24:56.033+0000] {processor.py:842} WARNING - No viable dags retrieved from /opt/airflow/dags/dag.py
[2024-09-16T21:24:56.050+0000] {processor.py:183} INFO - Processing /opt/airflow/dags/dag.py took 0.461 seconds
[2024-09-16T21:25:26.167+0000] {processor.py:161} INFO - Started process (PID=438) to work on /opt/airflow/dags/dag.py
[2024-09-16T21:25:26.168+0000] {processor.py:830} INFO - Processing file /opt/airflow/dags/dag.py for tasks to queue
[2024-09-16T21:25:26.169+0000] {logging_mixin.py:188} INFO - [2024-09-16T21:25:26.169+0000] {dagbag.py:545} INFO - Filling up the DagBag from /opt/airflow/dags/dag.py
[2024-09-16T21:25:26.563+0000] {logging_mixin.py:188} INFO - [2024-09-16T21:25:26.560+0000] {dagbag.py:355} ERROR - Failed to import: /opt/airflow/dags/dag.py
Traceback (most recent call last):
  File "/home/airflow/.local/lib/python3.12/site-packages/airflow/models/dagbag.py", line 351, in parse
    loader.exec_module(new_module)
  File "<frozen importlib._bootstrap_external>", line 995, in exec_module
  File "<frozen importlib._bootstrap>", line 488, in _call_with_frames_removed
  File "/opt/airflow/dags/dag.py", line 8, in <module>
    with DAG(
         ^^^^
  File "/home/airflow/.local/lib/python3.12/site-packages/airflow/models/dag.py", line 519, in __init__
    validate_key(dag_id)
  File "/home/airflow/.local/lib/python3.12/site-packages/airflow/utils/helpers.py", line 57, in validate_key
    raise AirflowException(
airflow.exceptions.AirflowException: The key '' has to be made of alphanumeric characters, dashes, dots and underscores exclusively
[2024-09-16T21:25:26.563+0000] {processor.py:842} WARNING - No viable dags retrieved from /opt/airflow/dags/dag.py
[2024-09-16T21:25:26.593+0000] {processor.py:183} INFO - Processing /opt/airflow/dags/dag.py took 0.430 seconds
[2024-09-16T21:25:56.708+0000] {processor.py:161} INFO - Started process (PID=447) to work on /opt/airflow/dags/dag.py
[2024-09-16T21:25:56.709+0000] {processor.py:830} INFO - Processing file /opt/airflow/dags/dag.py for tasks to queue
[2024-09-16T21:25:56.712+0000] {logging_mixin.py:188} INFO - [2024-09-16T21:25:56.712+0000] {dagbag.py:545} INFO - Filling up the DagBag from /opt/airflow/dags/dag.py
[2024-09-16T21:25:57.183+0000] {logging_mixin.py:188} INFO - [2024-09-16T21:25:57.182+0000] {dagbag.py:355} ERROR - Failed to import: /opt/airflow/dags/dag.py
Traceback (most recent call last):
  File "/home/airflow/.local/lib/python3.12/site-packages/airflow/models/dagbag.py", line 351, in parse
    loader.exec_module(new_module)
  File "<frozen importlib._bootstrap_external>", line 995, in exec_module
  File "<frozen importlib._bootstrap>", line 488, in _call_with_frames_removed
  File "/opt/airflow/dags/dag.py", line 8, in <module>
    with DAG(
         ^^^^
  File "/home/airflow/.local/lib/python3.12/site-packages/airflow/models/dag.py", line 519, in __init__
    validate_key(dag_id)
  File "/home/airflow/.local/lib/python3.12/site-packages/airflow/utils/helpers.py", line 57, in validate_key
    raise AirflowException(
airflow.exceptions.AirflowException: The key '' has to be made of alphanumeric characters, dashes, dots and underscores exclusively
[2024-09-16T21:25:57.184+0000] {processor.py:842} WARNING - No viable dags retrieved from /opt/airflow/dags/dag.py
[2024-09-16T21:25:57.202+0000] {processor.py:183} INFO - Processing /opt/airflow/dags/dag.py took 0.500 seconds
[2024-09-16T21:26:27.320+0000] {processor.py:161} INFO - Started process (PID=456) to work on /opt/airflow/dags/dag.py
[2024-09-16T21:26:27.321+0000] {processor.py:830} INFO - Processing file /opt/airflow/dags/dag.py for tasks to queue
[2024-09-16T21:26:27.322+0000] {logging_mixin.py:188} INFO - [2024-09-16T21:26:27.322+0000] {dagbag.py:545} INFO - Filling up the DagBag from /opt/airflow/dags/dag.py
[2024-09-16T21:26:27.829+0000] {logging_mixin.py:188} INFO - [2024-09-16T21:26:27.827+0000] {dagbag.py:355} ERROR - Failed to import: /opt/airflow/dags/dag.py
Traceback (most recent call last):
  File "/home/airflow/.local/lib/python3.12/site-packages/airflow/models/dagbag.py", line 351, in parse
    loader.exec_module(new_module)
  File "<frozen importlib._bootstrap_external>", line 995, in exec_module
  File "<frozen importlib._bootstrap>", line 488, in _call_with_frames_removed
  File "/opt/airflow/dags/dag.py", line 8, in <module>
    with DAG(
         ^^^^
  File "/home/airflow/.local/lib/python3.12/site-packages/airflow/models/dag.py", line 519, in __init__
    validate_key(dag_id)
  File "/home/airflow/.local/lib/python3.12/site-packages/airflow/utils/helpers.py", line 57, in validate_key
    raise AirflowException(
airflow.exceptions.AirflowException: The key '' has to be made of alphanumeric characters, dashes, dots and underscores exclusively
[2024-09-16T21:26:27.829+0000] {processor.py:842} WARNING - No viable dags retrieved from /opt/airflow/dags/dag.py
[2024-09-16T21:26:27.851+0000] {processor.py:183} INFO - Processing /opt/airflow/dags/dag.py took 0.535 seconds
[2024-09-16T21:26:57.950+0000] {processor.py:161} INFO - Started process (PID=464) to work on /opt/airflow/dags/dag.py
[2024-09-16T21:26:57.951+0000] {processor.py:830} INFO - Processing file /opt/airflow/dags/dag.py for tasks to queue
[2024-09-16T21:26:57.957+0000] {logging_mixin.py:188} INFO - [2024-09-16T21:26:57.957+0000] {dagbag.py:545} INFO - Filling up the DagBag from /opt/airflow/dags/dag.py
[2024-09-16T21:26:59.169+0000] {logging_mixin.py:188} INFO - [2024-09-16T21:26:59.167+0000] {dagbag.py:355} ERROR - Failed to import: /opt/airflow/dags/dag.py
Traceback (most recent call last):
  File "/home/airflow/.local/lib/python3.12/site-packages/airflow/models/dagbag.py", line 351, in parse
    loader.exec_module(new_module)
  File "<frozen importlib._bootstrap_external>", line 995, in exec_module
  File "<frozen importlib._bootstrap>", line 488, in _call_with_frames_removed
  File "/opt/airflow/dags/dag.py", line 8, in <module>
    with DAG(
         ^^^^
  File "/home/airflow/.local/lib/python3.12/site-packages/airflow/models/dag.py", line 519, in __init__
    validate_key(dag_id)
  File "/home/airflow/.local/lib/python3.12/site-packages/airflow/utils/helpers.py", line 57, in validate_key
    raise AirflowException(
airflow.exceptions.AirflowException: The key '' has to be made of alphanumeric characters, dashes, dots and underscores exclusively
[2024-09-16T21:26:59.170+0000] {processor.py:842} WARNING - No viable dags retrieved from /opt/airflow/dags/dag.py
[2024-09-16T21:26:59.197+0000] {processor.py:183} INFO - Processing /opt/airflow/dags/dag.py took 1.262 seconds
[2024-09-16T21:27:29.339+0000] {processor.py:161} INFO - Started process (PID=471) to work on /opt/airflow/dags/dag.py
[2024-09-16T21:27:29.340+0000] {processor.py:830} INFO - Processing file /opt/airflow/dags/dag.py for tasks to queue
[2024-09-16T21:27:29.341+0000] {logging_mixin.py:188} INFO - [2024-09-16T21:27:29.341+0000] {dagbag.py:545} INFO - Filling up the DagBag from /opt/airflow/dags/dag.py
[2024-09-16T21:27:29.807+0000] {logging_mixin.py:188} INFO - [2024-09-16T21:27:29.805+0000] {dagbag.py:355} ERROR - Failed to import: /opt/airflow/dags/dag.py
Traceback (most recent call last):
  File "/home/airflow/.local/lib/python3.12/site-packages/airflow/models/dagbag.py", line 351, in parse
    loader.exec_module(new_module)
  File "<frozen importlib._bootstrap_external>", line 995, in exec_module
  File "<frozen importlib._bootstrap>", line 488, in _call_with_frames_removed
  File "/opt/airflow/dags/dag.py", line 8, in <module>
    with DAG(
         ^^^^
  File "/home/airflow/.local/lib/python3.12/site-packages/airflow/models/dag.py", line 519, in __init__
    validate_key(dag_id)
  File "/home/airflow/.local/lib/python3.12/site-packages/airflow/utils/helpers.py", line 57, in validate_key
    raise AirflowException(
airflow.exceptions.AirflowException: The key '' has to be made of alphanumeric characters, dashes, dots and underscores exclusively
[2024-09-16T21:27:29.807+0000] {processor.py:842} WARNING - No viable dags retrieved from /opt/airflow/dags/dag.py
[2024-09-16T21:27:29.826+0000] {processor.py:183} INFO - Processing /opt/airflow/dags/dag.py took 0.492 seconds
[2024-09-16T21:27:59.957+0000] {processor.py:161} INFO - Started process (PID=479) to work on /opt/airflow/dags/dag.py
[2024-09-16T21:27:59.958+0000] {processor.py:830} INFO - Processing file /opt/airflow/dags/dag.py for tasks to queue
[2024-09-16T21:27:59.959+0000] {logging_mixin.py:188} INFO - [2024-09-16T21:27:59.959+0000] {dagbag.py:545} INFO - Filling up the DagBag from /opt/airflow/dags/dag.py
[2024-09-16T21:28:00.523+0000] {logging_mixin.py:188} INFO - [2024-09-16T21:28:00.521+0000] {dagbag.py:355} ERROR - Failed to import: /opt/airflow/dags/dag.py
Traceback (most recent call last):
  File "/home/airflow/.local/lib/python3.12/site-packages/airflow/models/dagbag.py", line 351, in parse
    loader.exec_module(new_module)
  File "<frozen importlib._bootstrap_external>", line 995, in exec_module
  File "<frozen importlib._bootstrap>", line 488, in _call_with_frames_removed
  File "/opt/airflow/dags/dag.py", line 8, in <module>
    with DAG(
         ^^^^
  File "/home/airflow/.local/lib/python3.12/site-packages/airflow/models/dag.py", line 519, in __init__
    validate_key(dag_id)
  File "/home/airflow/.local/lib/python3.12/site-packages/airflow/utils/helpers.py", line 57, in validate_key
    raise AirflowException(
airflow.exceptions.AirflowException: The key '' has to be made of alphanumeric characters, dashes, dots and underscores exclusively
[2024-09-16T21:28:00.523+0000] {processor.py:842} WARNING - No viable dags retrieved from /opt/airflow/dags/dag.py
[2024-09-16T21:28:00.546+0000] {processor.py:183} INFO - Processing /opt/airflow/dags/dag.py took 0.594 seconds
[2024-09-16T21:28:30.649+0000] {processor.py:161} INFO - Started process (PID=493) to work on /opt/airflow/dags/dag.py
[2024-09-16T21:28:30.650+0000] {processor.py:830} INFO - Processing file /opt/airflow/dags/dag.py for tasks to queue
[2024-09-16T21:28:30.651+0000] {logging_mixin.py:188} INFO - [2024-09-16T21:28:30.651+0000] {dagbag.py:545} INFO - Filling up the DagBag from /opt/airflow/dags/dag.py
[2024-09-16T21:28:31.117+0000] {logging_mixin.py:188} INFO - [2024-09-16T21:28:31.115+0000] {dagbag.py:355} ERROR - Failed to import: /opt/airflow/dags/dag.py
Traceback (most recent call last):
  File "/home/airflow/.local/lib/python3.12/site-packages/airflow/models/dagbag.py", line 351, in parse
    loader.exec_module(new_module)
  File "<frozen importlib._bootstrap_external>", line 995, in exec_module
  File "<frozen importlib._bootstrap>", line 488, in _call_with_frames_removed
  File "/opt/airflow/dags/dag.py", line 8, in <module>
    with DAG(
         ^^^^
  File "/home/airflow/.local/lib/python3.12/site-packages/airflow/models/dag.py", line 519, in __init__
    validate_key(dag_id)
  File "/home/airflow/.local/lib/python3.12/site-packages/airflow/utils/helpers.py", line 57, in validate_key
    raise AirflowException(
airflow.exceptions.AirflowException: The key '' has to be made of alphanumeric characters, dashes, dots and underscores exclusively
[2024-09-16T21:28:31.117+0000] {processor.py:842} WARNING - No viable dags retrieved from /opt/airflow/dags/dag.py
[2024-09-16T21:28:31.146+0000] {processor.py:183} INFO - Processing /opt/airflow/dags/dag.py took 0.502 seconds
[2024-09-16T21:29:01.265+0000] {processor.py:161} INFO - Started process (PID=502) to work on /opt/airflow/dags/dag.py
[2024-09-16T21:29:01.266+0000] {processor.py:830} INFO - Processing file /opt/airflow/dags/dag.py for tasks to queue
[2024-09-16T21:29:01.267+0000] {logging_mixin.py:188} INFO - [2024-09-16T21:29:01.267+0000] {dagbag.py:545} INFO - Filling up the DagBag from /opt/airflow/dags/dag.py
[2024-09-16T21:29:01.737+0000] {logging_mixin.py:188} INFO - [2024-09-16T21:29:01.734+0000] {dagbag.py:355} ERROR - Failed to import: /opt/airflow/dags/dag.py
Traceback (most recent call last):
  File "/home/airflow/.local/lib/python3.12/site-packages/airflow/models/dagbag.py", line 351, in parse
    loader.exec_module(new_module)
  File "<frozen importlib._bootstrap_external>", line 995, in exec_module
  File "<frozen importlib._bootstrap>", line 488, in _call_with_frames_removed
  File "/opt/airflow/dags/dag.py", line 8, in <module>
    with DAG(
         ^^^^
  File "/home/airflow/.local/lib/python3.12/site-packages/airflow/models/dag.py", line 519, in __init__
    validate_key(dag_id)
  File "/home/airflow/.local/lib/python3.12/site-packages/airflow/utils/helpers.py", line 57, in validate_key
    raise AirflowException(
airflow.exceptions.AirflowException: The key '' has to be made of alphanumeric characters, dashes, dots and underscores exclusively
[2024-09-16T21:29:01.739+0000] {processor.py:842} WARNING - No viable dags retrieved from /opt/airflow/dags/dag.py
[2024-09-16T21:29:01.761+0000] {processor.py:183} INFO - Processing /opt/airflow/dags/dag.py took 0.501 seconds
[2024-09-16T21:29:31.857+0000] {processor.py:161} INFO - Started process (PID=510) to work on /opt/airflow/dags/dag.py
[2024-09-16T21:29:31.858+0000] {processor.py:830} INFO - Processing file /opt/airflow/dags/dag.py for tasks to queue
[2024-09-16T21:29:31.859+0000] {logging_mixin.py:188} INFO - [2024-09-16T21:29:31.859+0000] {dagbag.py:545} INFO - Filling up the DagBag from /opt/airflow/dags/dag.py
[2024-09-16T21:29:32.297+0000] {logging_mixin.py:188} INFO - [2024-09-16T21:29:32.295+0000] {dagbag.py:355} ERROR - Failed to import: /opt/airflow/dags/dag.py
Traceback (most recent call last):
  File "/home/airflow/.local/lib/python3.12/site-packages/airflow/models/dagbag.py", line 351, in parse
    loader.exec_module(new_module)
  File "<frozen importlib._bootstrap_external>", line 995, in exec_module
  File "<frozen importlib._bootstrap>", line 488, in _call_with_frames_removed
  File "/opt/airflow/dags/dag.py", line 8, in <module>
    with DAG(
         ^^^^
  File "/home/airflow/.local/lib/python3.12/site-packages/airflow/models/dag.py", line 519, in __init__
    validate_key(dag_id)
  File "/home/airflow/.local/lib/python3.12/site-packages/airflow/utils/helpers.py", line 57, in validate_key
    raise AirflowException(
airflow.exceptions.AirflowException: The key '' has to be made of alphanumeric characters, dashes, dots and underscores exclusively
[2024-09-16T21:29:32.297+0000] {processor.py:842} WARNING - No viable dags retrieved from /opt/airflow/dags/dag.py
[2024-09-16T21:29:32.314+0000] {processor.py:183} INFO - Processing /opt/airflow/dags/dag.py took 0.461 seconds
[2024-09-16T21:30:02.426+0000] {processor.py:161} INFO - Started process (PID=518) to work on /opt/airflow/dags/dag.py
[2024-09-16T21:30:02.427+0000] {processor.py:830} INFO - Processing file /opt/airflow/dags/dag.py for tasks to queue
[2024-09-16T21:30:02.428+0000] {logging_mixin.py:188} INFO - [2024-09-16T21:30:02.428+0000] {dagbag.py:545} INFO - Filling up the DagBag from /opt/airflow/dags/dag.py
[2024-09-16T21:30:02.931+0000] {logging_mixin.py:188} INFO - [2024-09-16T21:30:02.929+0000] {dagbag.py:355} ERROR - Failed to import: /opt/airflow/dags/dag.py
Traceback (most recent call last):
  File "/home/airflow/.local/lib/python3.12/site-packages/airflow/models/dagbag.py", line 351, in parse
    loader.exec_module(new_module)
  File "<frozen importlib._bootstrap_external>", line 995, in exec_module
  File "<frozen importlib._bootstrap>", line 488, in _call_with_frames_removed
  File "/opt/airflow/dags/dag.py", line 8, in <module>
    with DAG(
         ^^^^
  File "/home/airflow/.local/lib/python3.12/site-packages/airflow/models/dag.py", line 519, in __init__
    validate_key(dag_id)
  File "/home/airflow/.local/lib/python3.12/site-packages/airflow/utils/helpers.py", line 57, in validate_key
    raise AirflowException(
airflow.exceptions.AirflowException: The key '' has to be made of alphanumeric characters, dashes, dots and underscores exclusively
[2024-09-16T21:30:02.932+0000] {processor.py:842} WARNING - No viable dags retrieved from /opt/airflow/dags/dag.py
[2024-09-16T21:30:02.956+0000] {processor.py:183} INFO - Processing /opt/airflow/dags/dag.py took 0.535 seconds
[2024-09-16T21:30:33.080+0000] {processor.py:161} INFO - Started process (PID=526) to work on /opt/airflow/dags/dag.py
[2024-09-16T21:30:33.081+0000] {processor.py:830} INFO - Processing file /opt/airflow/dags/dag.py for tasks to queue
[2024-09-16T21:30:33.082+0000] {logging_mixin.py:188} INFO - [2024-09-16T21:30:33.082+0000] {dagbag.py:545} INFO - Filling up the DagBag from /opt/airflow/dags/dag.py
[2024-09-16T21:30:33.523+0000] {logging_mixin.py:188} INFO - [2024-09-16T21:30:33.522+0000] {dagbag.py:355} ERROR - Failed to import: /opt/airflow/dags/dag.py
Traceback (most recent call last):
  File "/home/airflow/.local/lib/python3.12/site-packages/airflow/models/dagbag.py", line 351, in parse
    loader.exec_module(new_module)
  File "<frozen importlib._bootstrap_external>", line 995, in exec_module
  File "<frozen importlib._bootstrap>", line 488, in _call_with_frames_removed
  File "/opt/airflow/dags/dag.py", line 8, in <module>
    with DAG(
         ^^^^
  File "/home/airflow/.local/lib/python3.12/site-packages/airflow/models/dag.py", line 519, in __init__
    validate_key(dag_id)
  File "/home/airflow/.local/lib/python3.12/site-packages/airflow/utils/helpers.py", line 57, in validate_key
    raise AirflowException(
airflow.exceptions.AirflowException: The key '' has to be made of alphanumeric characters, dashes, dots and underscores exclusively
[2024-09-16T21:30:33.524+0000] {processor.py:842} WARNING - No viable dags retrieved from /opt/airflow/dags/dag.py
[2024-09-16T21:30:33.543+0000] {processor.py:183} INFO - Processing /opt/airflow/dags/dag.py took 0.468 seconds
[2024-09-16T21:31:03.663+0000] {processor.py:161} INFO - Started process (PID=534) to work on /opt/airflow/dags/dag.py
[2024-09-16T21:31:03.663+0000] {processor.py:830} INFO - Processing file /opt/airflow/dags/dag.py for tasks to queue
[2024-09-16T21:31:03.665+0000] {logging_mixin.py:188} INFO - [2024-09-16T21:31:03.665+0000] {dagbag.py:545} INFO - Filling up the DagBag from /opt/airflow/dags/dag.py
[2024-09-16T21:31:04.136+0000] {logging_mixin.py:188} INFO - [2024-09-16T21:31:04.134+0000] {dagbag.py:355} ERROR - Failed to import: /opt/airflow/dags/dag.py
Traceback (most recent call last):
  File "/home/airflow/.local/lib/python3.12/site-packages/airflow/models/dagbag.py", line 351, in parse
    loader.exec_module(new_module)
  File "<frozen importlib._bootstrap_external>", line 995, in exec_module
  File "<frozen importlib._bootstrap>", line 488, in _call_with_frames_removed
  File "/opt/airflow/dags/dag.py", line 8, in <module>
    with DAG(
         ^^^^
  File "/home/airflow/.local/lib/python3.12/site-packages/airflow/models/dag.py", line 519, in __init__
    validate_key(dag_id)
  File "/home/airflow/.local/lib/python3.12/site-packages/airflow/utils/helpers.py", line 57, in validate_key
    raise AirflowException(
airflow.exceptions.AirflowException: The key '' has to be made of alphanumeric characters, dashes, dots and underscores exclusively
[2024-09-16T21:31:04.136+0000] {processor.py:842} WARNING - No viable dags retrieved from /opt/airflow/dags/dag.py
[2024-09-16T21:31:04.154+0000] {processor.py:183} INFO - Processing /opt/airflow/dags/dag.py took 0.496 seconds
[2024-09-16T21:31:34.309+0000] {processor.py:161} INFO - Started process (PID=542) to work on /opt/airflow/dags/dag.py
[2024-09-16T21:31:34.309+0000] {processor.py:830} INFO - Processing file /opt/airflow/dags/dag.py for tasks to queue
[2024-09-16T21:31:34.310+0000] {logging_mixin.py:188} INFO - [2024-09-16T21:31:34.310+0000] {dagbag.py:545} INFO - Filling up the DagBag from /opt/airflow/dags/dag.py
[2024-09-16T21:31:34.803+0000] {logging_mixin.py:188} INFO - [2024-09-16T21:31:34.801+0000] {dagbag.py:355} ERROR - Failed to import: /opt/airflow/dags/dag.py
Traceback (most recent call last):
  File "/home/airflow/.local/lib/python3.12/site-packages/airflow/models/dagbag.py", line 351, in parse
    loader.exec_module(new_module)
  File "<frozen importlib._bootstrap_external>", line 995, in exec_module
  File "<frozen importlib._bootstrap>", line 488, in _call_with_frames_removed
  File "/opt/airflow/dags/dag.py", line 8, in <module>
    with DAG(
         ^^^^
  File "/home/airflow/.local/lib/python3.12/site-packages/airflow/models/dag.py", line 519, in __init__
    validate_key(dag_id)
  File "/home/airflow/.local/lib/python3.12/site-packages/airflow/utils/helpers.py", line 57, in validate_key
    raise AirflowException(
airflow.exceptions.AirflowException: The key '' has to be made of alphanumeric characters, dashes, dots and underscores exclusively
[2024-09-16T21:31:34.803+0000] {processor.py:842} WARNING - No viable dags retrieved from /opt/airflow/dags/dag.py
[2024-09-16T21:31:34.822+0000] {processor.py:183} INFO - Processing /opt/airflow/dags/dag.py took 0.520 seconds
[2024-09-16T21:32:04.944+0000] {processor.py:161} INFO - Started process (PID=550) to work on /opt/airflow/dags/dag.py
[2024-09-16T21:32:04.945+0000] {processor.py:830} INFO - Processing file /opt/airflow/dags/dag.py for tasks to queue
[2024-09-16T21:32:04.946+0000] {logging_mixin.py:188} INFO - [2024-09-16T21:32:04.946+0000] {dagbag.py:545} INFO - Filling up the DagBag from /opt/airflow/dags/dag.py
[2024-09-16T21:32:05.394+0000] {logging_mixin.py:188} INFO - [2024-09-16T21:32:05.392+0000] {dagbag.py:355} ERROR - Failed to import: /opt/airflow/dags/dag.py
Traceback (most recent call last):
  File "/home/airflow/.local/lib/python3.12/site-packages/airflow/models/dagbag.py", line 351, in parse
    loader.exec_module(new_module)
  File "<frozen importlib._bootstrap_external>", line 995, in exec_module
  File "<frozen importlib._bootstrap>", line 488, in _call_with_frames_removed
  File "/opt/airflow/dags/dag.py", line 8, in <module>
    with DAG(
         ^^^^
  File "/home/airflow/.local/lib/python3.12/site-packages/airflow/models/dag.py", line 519, in __init__
    validate_key(dag_id)
  File "/home/airflow/.local/lib/python3.12/site-packages/airflow/utils/helpers.py", line 57, in validate_key
    raise AirflowException(
airflow.exceptions.AirflowException: The key '' has to be made of alphanumeric characters, dashes, dots and underscores exclusively
[2024-09-16T21:32:05.394+0000] {processor.py:842} WARNING - No viable dags retrieved from /opt/airflow/dags/dag.py
[2024-09-16T21:32:05.418+0000] {processor.py:183} INFO - Processing /opt/airflow/dags/dag.py took 0.479 seconds
[2024-09-16T21:32:35.578+0000] {processor.py:161} INFO - Started process (PID=558) to work on /opt/airflow/dags/dag.py
[2024-09-16T21:32:35.580+0000] {processor.py:830} INFO - Processing file /opt/airflow/dags/dag.py for tasks to queue
[2024-09-16T21:32:35.581+0000] {logging_mixin.py:188} INFO - [2024-09-16T21:32:35.581+0000] {dagbag.py:545} INFO - Filling up the DagBag from /opt/airflow/dags/dag.py
[2024-09-16T21:32:36.632+0000] {logging_mixin.py:188} INFO - [2024-09-16T21:32:36.630+0000] {dagbag.py:355} ERROR - Failed to import: /opt/airflow/dags/dag.py
Traceback (most recent call last):
  File "/home/airflow/.local/lib/python3.12/site-packages/airflow/models/dagbag.py", line 351, in parse
    loader.exec_module(new_module)
  File "<frozen importlib._bootstrap_external>", line 995, in exec_module
  File "<frozen importlib._bootstrap>", line 488, in _call_with_frames_removed
  File "/opt/airflow/dags/dag.py", line 8, in <module>
    with DAG(
         ^^^^
  File "/home/airflow/.local/lib/python3.12/site-packages/airflow/models/dag.py", line 519, in __init__
    validate_key(dag_id)
  File "/home/airflow/.local/lib/python3.12/site-packages/airflow/utils/helpers.py", line 57, in validate_key
    raise AirflowException(
airflow.exceptions.AirflowException: The key '' has to be made of alphanumeric characters, dashes, dots and underscores exclusively
[2024-09-16T21:32:36.633+0000] {processor.py:842} WARNING - No viable dags retrieved from /opt/airflow/dags/dag.py
[2024-09-16T21:32:36.657+0000] {processor.py:183} INFO - Processing /opt/airflow/dags/dag.py took 1.091 seconds
[2024-09-16T21:33:06.783+0000] {processor.py:161} INFO - Started process (PID=566) to work on /opt/airflow/dags/dag.py
[2024-09-16T21:33:06.784+0000] {processor.py:830} INFO - Processing file /opt/airflow/dags/dag.py for tasks to queue
[2024-09-16T21:33:06.786+0000] {logging_mixin.py:188} INFO - [2024-09-16T21:33:06.785+0000] {dagbag.py:545} INFO - Filling up the DagBag from /opt/airflow/dags/dag.py
[2024-09-16T21:33:07.650+0000] {logging_mixin.py:188} INFO - [2024-09-16T21:33:07.647+0000] {dagbag.py:355} ERROR - Failed to import: /opt/airflow/dags/dag.py
Traceback (most recent call last):
  File "/home/airflow/.local/lib/python3.12/site-packages/airflow/models/dagbag.py", line 351, in parse
    loader.exec_module(new_module)
  File "<frozen importlib._bootstrap_external>", line 995, in exec_module
  File "<frozen importlib._bootstrap>", line 488, in _call_with_frames_removed
  File "/opt/airflow/dags/dag.py", line 8, in <module>
    with DAG(
         ^^^^
  File "/home/airflow/.local/lib/python3.12/site-packages/airflow/models/dag.py", line 519, in __init__
    validate_key(dag_id)
  File "/home/airflow/.local/lib/python3.12/site-packages/airflow/utils/helpers.py", line 57, in validate_key
    raise AirflowException(
airflow.exceptions.AirflowException: The key '' has to be made of alphanumeric characters, dashes, dots and underscores exclusively
[2024-09-16T21:33:07.651+0000] {processor.py:842} WARNING - No viable dags retrieved from /opt/airflow/dags/dag.py
[2024-09-16T21:33:07.675+0000] {processor.py:183} INFO - Processing /opt/airflow/dags/dag.py took 0.899 seconds
[2024-09-16T21:33:37.786+0000] {processor.py:161} INFO - Started process (PID=574) to work on /opt/airflow/dags/dag.py
[2024-09-16T21:33:37.787+0000] {processor.py:830} INFO - Processing file /opt/airflow/dags/dag.py for tasks to queue
[2024-09-16T21:33:37.788+0000] {logging_mixin.py:188} INFO - [2024-09-16T21:33:37.788+0000] {dagbag.py:545} INFO - Filling up the DagBag from /opt/airflow/dags/dag.py
[2024-09-16T21:33:38.294+0000] {logging_mixin.py:188} INFO - [2024-09-16T21:33:38.291+0000] {dagbag.py:355} ERROR - Failed to import: /opt/airflow/dags/dag.py
Traceback (most recent call last):
  File "/home/airflow/.local/lib/python3.12/site-packages/airflow/models/dagbag.py", line 351, in parse
    loader.exec_module(new_module)
  File "<frozen importlib._bootstrap_external>", line 995, in exec_module
  File "<frozen importlib._bootstrap>", line 488, in _call_with_frames_removed
  File "/opt/airflow/dags/dag.py", line 8, in <module>
    with DAG(
         ^^^^
  File "/home/airflow/.local/lib/python3.12/site-packages/airflow/models/dag.py", line 519, in __init__
    validate_key(dag_id)
  File "/home/airflow/.local/lib/python3.12/site-packages/airflow/utils/helpers.py", line 57, in validate_key
    raise AirflowException(
airflow.exceptions.AirflowException: The key '' has to be made of alphanumeric characters, dashes, dots and underscores exclusively
[2024-09-16T21:33:38.294+0000] {processor.py:842} WARNING - No viable dags retrieved from /opt/airflow/dags/dag.py
[2024-09-16T21:33:38.318+0000] {processor.py:183} INFO - Processing /opt/airflow/dags/dag.py took 0.537 seconds
[2024-09-16T21:34:08.433+0000] {processor.py:161} INFO - Started process (PID=582) to work on /opt/airflow/dags/dag.py
[2024-09-16T21:34:08.434+0000] {processor.py:830} INFO - Processing file /opt/airflow/dags/dag.py for tasks to queue
[2024-09-16T21:34:08.436+0000] {logging_mixin.py:188} INFO - [2024-09-16T21:34:08.435+0000] {dagbag.py:545} INFO - Filling up the DagBag from /opt/airflow/dags/dag.py
[2024-09-16T21:34:08.954+0000] {logging_mixin.py:188} INFO - [2024-09-16T21:34:08.952+0000] {dagbag.py:355} ERROR - Failed to import: /opt/airflow/dags/dag.py
Traceback (most recent call last):
  File "/home/airflow/.local/lib/python3.12/site-packages/airflow/models/dagbag.py", line 351, in parse
    loader.exec_module(new_module)
  File "<frozen importlib._bootstrap_external>", line 995, in exec_module
  File "<frozen importlib._bootstrap>", line 488, in _call_with_frames_removed
  File "/opt/airflow/dags/dag.py", line 8, in <module>
    with DAG(
         ^^^^
  File "/home/airflow/.local/lib/python3.12/site-packages/airflow/models/dag.py", line 519, in __init__
    validate_key(dag_id)
  File "/home/airflow/.local/lib/python3.12/site-packages/airflow/utils/helpers.py", line 57, in validate_key
    raise AirflowException(
airflow.exceptions.AirflowException: The key '' has to be made of alphanumeric characters, dashes, dots and underscores exclusively
[2024-09-16T21:34:08.954+0000] {processor.py:842} WARNING - No viable dags retrieved from /opt/airflow/dags/dag.py
[2024-09-16T21:34:08.972+0000] {processor.py:183} INFO - Processing /opt/airflow/dags/dag.py took 0.543 seconds
[2024-09-16T21:34:39.075+0000] {processor.py:161} INFO - Started process (PID=591) to work on /opt/airflow/dags/dag.py
[2024-09-16T21:34:39.076+0000] {processor.py:830} INFO - Processing file /opt/airflow/dags/dag.py for tasks to queue
[2024-09-16T21:34:39.077+0000] {logging_mixin.py:188} INFO - [2024-09-16T21:34:39.077+0000] {dagbag.py:545} INFO - Filling up the DagBag from /opt/airflow/dags/dag.py
[2024-09-16T21:34:39.582+0000] {logging_mixin.py:188} INFO - [2024-09-16T21:34:39.581+0000] {dagbag.py:355} ERROR - Failed to import: /opt/airflow/dags/dag.py
Traceback (most recent call last):
  File "/home/airflow/.local/lib/python3.12/site-packages/airflow/models/dagbag.py", line 351, in parse
    loader.exec_module(new_module)
  File "<frozen importlib._bootstrap_external>", line 995, in exec_module
  File "<frozen importlib._bootstrap>", line 488, in _call_with_frames_removed
  File "/opt/airflow/dags/dag.py", line 8, in <module>
    with DAG(
         ^^^^
  File "/home/airflow/.local/lib/python3.12/site-packages/airflow/models/dag.py", line 519, in __init__
    validate_key(dag_id)
  File "/home/airflow/.local/lib/python3.12/site-packages/airflow/utils/helpers.py", line 57, in validate_key
    raise AirflowException(
airflow.exceptions.AirflowException: The key '' has to be made of alphanumeric characters, dashes, dots and underscores exclusively
[2024-09-16T21:34:39.583+0000] {processor.py:842} WARNING - No viable dags retrieved from /opt/airflow/dags/dag.py
[2024-09-16T21:34:39.604+0000] {processor.py:183} INFO - Processing /opt/airflow/dags/dag.py took 0.534 seconds
[2024-09-16T21:35:09.720+0000] {processor.py:161} INFO - Started process (PID=600) to work on /opt/airflow/dags/dag.py
[2024-09-16T21:35:09.721+0000] {processor.py:830} INFO - Processing file /opt/airflow/dags/dag.py for tasks to queue
[2024-09-16T21:35:09.722+0000] {logging_mixin.py:188} INFO - [2024-09-16T21:35:09.722+0000] {dagbag.py:545} INFO - Filling up the DagBag from /opt/airflow/dags/dag.py
[2024-09-16T21:35:10.168+0000] {logging_mixin.py:188} INFO - [2024-09-16T21:35:10.166+0000] {dagbag.py:355} ERROR - Failed to import: /opt/airflow/dags/dag.py
Traceback (most recent call last):
  File "/home/airflow/.local/lib/python3.12/site-packages/airflow/models/dagbag.py", line 351, in parse
    loader.exec_module(new_module)
  File "<frozen importlib._bootstrap_external>", line 995, in exec_module
  File "<frozen importlib._bootstrap>", line 488, in _call_with_frames_removed
  File "/opt/airflow/dags/dag.py", line 8, in <module>
    with DAG(
         ^^^^
  File "/home/airflow/.local/lib/python3.12/site-packages/airflow/models/dag.py", line 519, in __init__
    validate_key(dag_id)
  File "/home/airflow/.local/lib/python3.12/site-packages/airflow/utils/helpers.py", line 57, in validate_key
    raise AirflowException(
airflow.exceptions.AirflowException: The key '' has to be made of alphanumeric characters, dashes, dots and underscores exclusively
[2024-09-16T21:35:10.168+0000] {processor.py:842} WARNING - No viable dags retrieved from /opt/airflow/dags/dag.py
[2024-09-16T21:35:10.195+0000] {processor.py:183} INFO - Processing /opt/airflow/dags/dag.py took 0.479 seconds
[2024-09-16T21:35:40.275+0000] {processor.py:161} INFO - Started process (PID=608) to work on /opt/airflow/dags/dag.py
[2024-09-16T21:35:40.275+0000] {processor.py:830} INFO - Processing file /opt/airflow/dags/dag.py for tasks to queue
[2024-09-16T21:35:40.277+0000] {logging_mixin.py:188} INFO - [2024-09-16T21:35:40.277+0000] {dagbag.py:545} INFO - Filling up the DagBag from /opt/airflow/dags/dag.py
[2024-09-16T21:35:40.763+0000] {logging_mixin.py:188} INFO - [2024-09-16T21:35:40.761+0000] {dagbag.py:355} ERROR - Failed to import: /opt/airflow/dags/dag.py
Traceback (most recent call last):
  File "/home/airflow/.local/lib/python3.12/site-packages/airflow/models/dagbag.py", line 351, in parse
    loader.exec_module(new_module)
  File "<frozen importlib._bootstrap_external>", line 995, in exec_module
  File "<frozen importlib._bootstrap>", line 488, in _call_with_frames_removed
  File "/opt/airflow/dags/dag.py", line 8, in <module>
    with DAG(
         ^^^^
  File "/home/airflow/.local/lib/python3.12/site-packages/airflow/models/dag.py", line 519, in __init__
    validate_key(dag_id)
  File "/home/airflow/.local/lib/python3.12/site-packages/airflow/utils/helpers.py", line 57, in validate_key
    raise AirflowException(
airflow.exceptions.AirflowException: The key '' has to be made of alphanumeric characters, dashes, dots and underscores exclusively
[2024-09-16T21:35:40.764+0000] {processor.py:842} WARNING - No viable dags retrieved from /opt/airflow/dags/dag.py
[2024-09-16T21:35:40.793+0000] {processor.py:183} INFO - Processing /opt/airflow/dags/dag.py took 0.525 seconds
[2024-09-16T21:36:10.909+0000] {processor.py:161} INFO - Started process (PID=616) to work on /opt/airflow/dags/dag.py
[2024-09-16T21:36:10.909+0000] {processor.py:830} INFO - Processing file /opt/airflow/dags/dag.py for tasks to queue
[2024-09-16T21:36:10.911+0000] {logging_mixin.py:188} INFO - [2024-09-16T21:36:10.911+0000] {dagbag.py:545} INFO - Filling up the DagBag from /opt/airflow/dags/dag.py
[2024-09-16T21:36:11.356+0000] {logging_mixin.py:188} INFO - [2024-09-16T21:36:11.354+0000] {dagbag.py:355} ERROR - Failed to import: /opt/airflow/dags/dag.py
Traceback (most recent call last):
  File "/home/airflow/.local/lib/python3.12/site-packages/airflow/models/dagbag.py", line 351, in parse
    loader.exec_module(new_module)
  File "<frozen importlib._bootstrap_external>", line 995, in exec_module
  File "<frozen importlib._bootstrap>", line 488, in _call_with_frames_removed
  File "/opt/airflow/dags/dag.py", line 8, in <module>
    with DAG(
         ^^^^
  File "/home/airflow/.local/lib/python3.12/site-packages/airflow/models/dag.py", line 519, in __init__
    validate_key(dag_id)
  File "/home/airflow/.local/lib/python3.12/site-packages/airflow/utils/helpers.py", line 57, in validate_key
    raise AirflowException(
airflow.exceptions.AirflowException: The key '' has to be made of alphanumeric characters, dashes, dots and underscores exclusively
[2024-09-16T21:36:11.356+0000] {processor.py:842} WARNING - No viable dags retrieved from /opt/airflow/dags/dag.py
[2024-09-16T21:36:11.376+0000] {processor.py:183} INFO - Processing /opt/airflow/dags/dag.py took 0.472 seconds
[2024-09-16T21:36:41.509+0000] {processor.py:161} INFO - Started process (PID=624) to work on /opt/airflow/dags/dag.py
[2024-09-16T21:36:41.509+0000] {processor.py:830} INFO - Processing file /opt/airflow/dags/dag.py for tasks to queue
[2024-09-16T21:36:41.511+0000] {logging_mixin.py:188} INFO - [2024-09-16T21:36:41.510+0000] {dagbag.py:545} INFO - Filling up the DagBag from /opt/airflow/dags/dag.py
[2024-09-16T21:36:41.966+0000] {logging_mixin.py:188} INFO - [2024-09-16T21:36:41.965+0000] {dagbag.py:355} ERROR - Failed to import: /opt/airflow/dags/dag.py
Traceback (most recent call last):
  File "/home/airflow/.local/lib/python3.12/site-packages/airflow/models/dagbag.py", line 351, in parse
    loader.exec_module(new_module)
  File "<frozen importlib._bootstrap_external>", line 995, in exec_module
  File "<frozen importlib._bootstrap>", line 488, in _call_with_frames_removed
  File "/opt/airflow/dags/dag.py", line 8, in <module>
    with DAG(
         ^^^^
  File "/home/airflow/.local/lib/python3.12/site-packages/airflow/models/dag.py", line 519, in __init__
    validate_key(dag_id)
  File "/home/airflow/.local/lib/python3.12/site-packages/airflow/utils/helpers.py", line 57, in validate_key
    raise AirflowException(
airflow.exceptions.AirflowException: The key '' has to be made of alphanumeric characters, dashes, dots and underscores exclusively
[2024-09-16T21:36:41.967+0000] {processor.py:842} WARNING - No viable dags retrieved from /opt/airflow/dags/dag.py
[2024-09-16T21:36:41.985+0000] {processor.py:183} INFO - Processing /opt/airflow/dags/dag.py took 0.481 seconds
[2024-09-16T21:37:12.098+0000] {processor.py:161} INFO - Started process (PID=633) to work on /opt/airflow/dags/dag.py
[2024-09-16T21:37:12.098+0000] {processor.py:830} INFO - Processing file /opt/airflow/dags/dag.py for tasks to queue
[2024-09-16T21:37:12.100+0000] {logging_mixin.py:188} INFO - [2024-09-16T21:37:12.099+0000] {dagbag.py:545} INFO - Filling up the DagBag from /opt/airflow/dags/dag.py
[2024-09-16T21:37:12.564+0000] {logging_mixin.py:188} INFO - [2024-09-16T21:37:12.562+0000] {dagbag.py:355} ERROR - Failed to import: /opt/airflow/dags/dag.py
Traceback (most recent call last):
  File "/home/airflow/.local/lib/python3.12/site-packages/airflow/models/dagbag.py", line 351, in parse
    loader.exec_module(new_module)
  File "<frozen importlib._bootstrap_external>", line 995, in exec_module
  File "<frozen importlib._bootstrap>", line 488, in _call_with_frames_removed
  File "/opt/airflow/dags/dag.py", line 8, in <module>
    with DAG(
         ^^^^
  File "/home/airflow/.local/lib/python3.12/site-packages/airflow/models/dag.py", line 519, in __init__
    validate_key(dag_id)
  File "/home/airflow/.local/lib/python3.12/site-packages/airflow/utils/helpers.py", line 57, in validate_key
    raise AirflowException(
airflow.exceptions.AirflowException: The key '' has to be made of alphanumeric characters, dashes, dots and underscores exclusively
[2024-09-16T21:37:12.565+0000] {processor.py:842} WARNING - No viable dags retrieved from /opt/airflow/dags/dag.py
[2024-09-16T21:37:12.582+0000] {processor.py:183} INFO - Processing /opt/airflow/dags/dag.py took 0.489 seconds
[2024-09-16T21:37:42.706+0000] {processor.py:161} INFO - Started process (PID=641) to work on /opt/airflow/dags/dag.py
[2024-09-16T21:37:42.706+0000] {processor.py:830} INFO - Processing file /opt/airflow/dags/dag.py for tasks to queue
[2024-09-16T21:37:42.708+0000] {logging_mixin.py:188} INFO - [2024-09-16T21:37:42.707+0000] {dagbag.py:545} INFO - Filling up the DagBag from /opt/airflow/dags/dag.py
[2024-09-16T21:37:43.154+0000] {logging_mixin.py:188} INFO - [2024-09-16T21:37:43.152+0000] {dagbag.py:355} ERROR - Failed to import: /opt/airflow/dags/dag.py
Traceback (most recent call last):
  File "/home/airflow/.local/lib/python3.12/site-packages/airflow/models/dagbag.py", line 351, in parse
    loader.exec_module(new_module)
  File "<frozen importlib._bootstrap_external>", line 995, in exec_module
  File "<frozen importlib._bootstrap>", line 488, in _call_with_frames_removed
  File "/opt/airflow/dags/dag.py", line 8, in <module>
    with DAG(
         ^^^^
  File "/home/airflow/.local/lib/python3.12/site-packages/airflow/models/dag.py", line 519, in __init__
    validate_key(dag_id)
  File "/home/airflow/.local/lib/python3.12/site-packages/airflow/utils/helpers.py", line 57, in validate_key
    raise AirflowException(
airflow.exceptions.AirflowException: The key '' has to be made of alphanumeric characters, dashes, dots and underscores exclusively
[2024-09-16T21:37:43.154+0000] {processor.py:842} WARNING - No viable dags retrieved from /opt/airflow/dags/dag.py
[2024-09-16T21:37:43.174+0000] {processor.py:183} INFO - Processing /opt/airflow/dags/dag.py took 0.473 seconds
[2024-09-16T21:38:13.287+0000] {processor.py:161} INFO - Started process (PID=649) to work on /opt/airflow/dags/dag.py
[2024-09-16T21:38:13.288+0000] {processor.py:830} INFO - Processing file /opt/airflow/dags/dag.py for tasks to queue
[2024-09-16T21:38:13.289+0000] {logging_mixin.py:188} INFO - [2024-09-16T21:38:13.289+0000] {dagbag.py:545} INFO - Filling up the DagBag from /opt/airflow/dags/dag.py
[2024-09-16T21:38:13.831+0000] {logging_mixin.py:188} INFO - [2024-09-16T21:38:13.829+0000] {dagbag.py:355} ERROR - Failed to import: /opt/airflow/dags/dag.py
Traceback (most recent call last):
  File "/home/airflow/.local/lib/python3.12/site-packages/airflow/models/dagbag.py", line 351, in parse
    loader.exec_module(new_module)
  File "<frozen importlib._bootstrap_external>", line 995, in exec_module
  File "<frozen importlib._bootstrap>", line 488, in _call_with_frames_removed
  File "/opt/airflow/dags/dag.py", line 8, in <module>
    with DAG(
         ^^^^
  File "/home/airflow/.local/lib/python3.12/site-packages/airflow/models/dag.py", line 519, in __init__
    validate_key(dag_id)
  File "/home/airflow/.local/lib/python3.12/site-packages/airflow/utils/helpers.py", line 57, in validate_key
    raise AirflowException(
airflow.exceptions.AirflowException: The key '' has to be made of alphanumeric characters, dashes, dots and underscores exclusively
[2024-09-16T21:38:13.832+0000] {processor.py:842} WARNING - No viable dags retrieved from /opt/airflow/dags/dag.py
[2024-09-16T21:38:13.869+0000] {processor.py:183} INFO - Processing /opt/airflow/dags/dag.py took 0.587 seconds
[2024-09-16T21:38:43.986+0000] {processor.py:161} INFO - Started process (PID=657) to work on /opt/airflow/dags/dag.py
[2024-09-16T21:38:43.986+0000] {processor.py:830} INFO - Processing file /opt/airflow/dags/dag.py for tasks to queue
[2024-09-16T21:38:43.988+0000] {logging_mixin.py:188} INFO - [2024-09-16T21:38:43.988+0000] {dagbag.py:545} INFO - Filling up the DagBag from /opt/airflow/dags/dag.py
[2024-09-16T21:38:44.439+0000] {logging_mixin.py:188} INFO - [2024-09-16T21:38:44.437+0000] {dagbag.py:355} ERROR - Failed to import: /opt/airflow/dags/dag.py
Traceback (most recent call last):
  File "/home/airflow/.local/lib/python3.12/site-packages/airflow/models/dagbag.py", line 351, in parse
    loader.exec_module(new_module)
  File "<frozen importlib._bootstrap_external>", line 995, in exec_module
  File "<frozen importlib._bootstrap>", line 488, in _call_with_frames_removed
  File "/opt/airflow/dags/dag.py", line 8, in <module>
    with DAG(
         ^^^^
  File "/home/airflow/.local/lib/python3.12/site-packages/airflow/models/dag.py", line 519, in __init__
    validate_key(dag_id)
  File "/home/airflow/.local/lib/python3.12/site-packages/airflow/utils/helpers.py", line 57, in validate_key
    raise AirflowException(
airflow.exceptions.AirflowException: The key '' has to be made of alphanumeric characters, dashes, dots and underscores exclusively
[2024-09-16T21:38:44.439+0000] {processor.py:842} WARNING - No viable dags retrieved from /opt/airflow/dags/dag.py
[2024-09-16T21:38:44.459+0000] {processor.py:183} INFO - Processing /opt/airflow/dags/dag.py took 0.478 seconds
[2024-09-16T21:39:14.498+0000] {processor.py:161} INFO - Started process (PID=666) to work on /opt/airflow/dags/dag.py
[2024-09-16T21:39:14.499+0000] {processor.py:830} INFO - Processing file /opt/airflow/dags/dag.py for tasks to queue
[2024-09-16T21:39:14.501+0000] {logging_mixin.py:188} INFO - [2024-09-16T21:39:14.501+0000] {dagbag.py:545} INFO - Filling up the DagBag from /opt/airflow/dags/dag.py
[2024-09-16T21:39:15.255+0000] {logging_mixin.py:188} INFO - [2024-09-16T21:39:15.253+0000] {dagbag.py:355} ERROR - Failed to import: /opt/airflow/dags/dag.py
Traceback (most recent call last):
  File "/home/airflow/.local/lib/python3.12/site-packages/airflow/models/dagbag.py", line 351, in parse
    loader.exec_module(new_module)
  File "<frozen importlib._bootstrap_external>", line 995, in exec_module
  File "<frozen importlib._bootstrap>", line 488, in _call_with_frames_removed
  File "/opt/airflow/dags/dag.py", line 8, in <module>
    with DAG(
         ^^^^
  File "/home/airflow/.local/lib/python3.12/site-packages/airflow/models/dag.py", line 519, in __init__
    validate_key(dag_id)
  File "/home/airflow/.local/lib/python3.12/site-packages/airflow/utils/helpers.py", line 57, in validate_key
    raise AirflowException(
airflow.exceptions.AirflowException: The key '' has to be made of alphanumeric characters, dashes, dots and underscores exclusively
[2024-09-16T21:39:15.256+0000] {processor.py:842} WARNING - No viable dags retrieved from /opt/airflow/dags/dag.py
[2024-09-16T21:39:15.281+0000] {processor.py:183} INFO - Processing /opt/airflow/dags/dag.py took 0.792 seconds
[2024-09-16T21:39:45.419+0000] {processor.py:161} INFO - Started process (PID=674) to work on /opt/airflow/dags/dag.py
[2024-09-16T21:39:45.419+0000] {processor.py:830} INFO - Processing file /opt/airflow/dags/dag.py for tasks to queue
[2024-09-16T21:39:45.421+0000] {logging_mixin.py:188} INFO - [2024-09-16T21:39:45.421+0000] {dagbag.py:545} INFO - Filling up the DagBag from /opt/airflow/dags/dag.py
[2024-09-16T21:39:45.899+0000] {logging_mixin.py:188} INFO - [2024-09-16T21:39:45.897+0000] {dagbag.py:355} ERROR - Failed to import: /opt/airflow/dags/dag.py
Traceback (most recent call last):
  File "/home/airflow/.local/lib/python3.12/site-packages/airflow/models/dagbag.py", line 351, in parse
    loader.exec_module(new_module)
  File "<frozen importlib._bootstrap_external>", line 995, in exec_module
  File "<frozen importlib._bootstrap>", line 488, in _call_with_frames_removed
  File "/opt/airflow/dags/dag.py", line 8, in <module>
    with DAG(
         ^^^^
  File "/home/airflow/.local/lib/python3.12/site-packages/airflow/models/dag.py", line 519, in __init__
    validate_key(dag_id)
  File "/home/airflow/.local/lib/python3.12/site-packages/airflow/utils/helpers.py", line 57, in validate_key
    raise AirflowException(
airflow.exceptions.AirflowException: The key '' has to be made of alphanumeric characters, dashes, dots and underscores exclusively
[2024-09-16T21:39:45.900+0000] {processor.py:842} WARNING - No viable dags retrieved from /opt/airflow/dags/dag.py
[2024-09-16T21:39:45.924+0000] {processor.py:183} INFO - Processing /opt/airflow/dags/dag.py took 0.510 seconds
[2024-09-16T21:40:16.048+0000] {processor.py:161} INFO - Started process (PID=683) to work on /opt/airflow/dags/dag.py
[2024-09-16T21:40:16.049+0000] {processor.py:830} INFO - Processing file /opt/airflow/dags/dag.py for tasks to queue
[2024-09-16T21:40:16.051+0000] {logging_mixin.py:188} INFO - [2024-09-16T21:40:16.051+0000] {dagbag.py:545} INFO - Filling up the DagBag from /opt/airflow/dags/dag.py
[2024-09-16T21:40:16.817+0000] {logging_mixin.py:188} INFO - [2024-09-16T21:40:16.814+0000] {dagbag.py:355} ERROR - Failed to import: /opt/airflow/dags/dag.py
Traceback (most recent call last):
  File "/home/airflow/.local/lib/python3.12/site-packages/airflow/models/dagbag.py", line 351, in parse
    loader.exec_module(new_module)
  File "<frozen importlib._bootstrap_external>", line 995, in exec_module
  File "<frozen importlib._bootstrap>", line 488, in _call_with_frames_removed
  File "/opt/airflow/dags/dag.py", line 8, in <module>
    with DAG(
         ^^^^
  File "/home/airflow/.local/lib/python3.12/site-packages/airflow/models/dag.py", line 519, in __init__
    validate_key(dag_id)
  File "/home/airflow/.local/lib/python3.12/site-packages/airflow/utils/helpers.py", line 57, in validate_key
    raise AirflowException(
airflow.exceptions.AirflowException: The key '' has to be made of alphanumeric characters, dashes, dots and underscores exclusively
[2024-09-16T21:40:16.823+0000] {processor.py:842} WARNING - No viable dags retrieved from /opt/airflow/dags/dag.py
[2024-09-16T21:40:16.852+0000] {processor.py:183} INFO - Processing /opt/airflow/dags/dag.py took 0.811 seconds
[2024-09-16T21:40:46.965+0000] {processor.py:161} INFO - Started process (PID=691) to work on /opt/airflow/dags/dag.py
[2024-09-16T21:40:46.966+0000] {processor.py:830} INFO - Processing file /opt/airflow/dags/dag.py for tasks to queue
[2024-09-16T21:40:46.967+0000] {logging_mixin.py:188} INFO - [2024-09-16T21:40:46.967+0000] {dagbag.py:545} INFO - Filling up the DagBag from /opt/airflow/dags/dag.py
[2024-09-16T21:40:47.531+0000] {logging_mixin.py:188} INFO - [2024-09-16T21:40:47.530+0000] {dagbag.py:355} ERROR - Failed to import: /opt/airflow/dags/dag.py
Traceback (most recent call last):
  File "/home/airflow/.local/lib/python3.12/site-packages/airflow/models/dagbag.py", line 351, in parse
    loader.exec_module(new_module)
  File "<frozen importlib._bootstrap_external>", line 995, in exec_module
  File "<frozen importlib._bootstrap>", line 488, in _call_with_frames_removed
  File "/opt/airflow/dags/dag.py", line 8, in <module>
    with DAG(
         ^^^^
  File "/home/airflow/.local/lib/python3.12/site-packages/airflow/models/dag.py", line 519, in __init__
    validate_key(dag_id)
  File "/home/airflow/.local/lib/python3.12/site-packages/airflow/utils/helpers.py", line 57, in validate_key
    raise AirflowException(
airflow.exceptions.AirflowException: The key '' has to be made of alphanumeric characters, dashes, dots and underscores exclusively
[2024-09-16T21:40:47.532+0000] {processor.py:842} WARNING - No viable dags retrieved from /opt/airflow/dags/dag.py
[2024-09-16T21:40:47.551+0000] {processor.py:183} INFO - Processing /opt/airflow/dags/dag.py took 0.593 seconds
[2024-09-16T21:41:17.675+0000] {processor.py:161} INFO - Started process (PID=699) to work on /opt/airflow/dags/dag.py
[2024-09-16T21:41:17.676+0000] {processor.py:830} INFO - Processing file /opt/airflow/dags/dag.py for tasks to queue
[2024-09-16T21:41:17.678+0000] {logging_mixin.py:188} INFO - [2024-09-16T21:41:17.678+0000] {dagbag.py:545} INFO - Filling up the DagBag from /opt/airflow/dags/dag.py
[2024-09-16T21:41:18.180+0000] {logging_mixin.py:188} INFO - [2024-09-16T21:41:18.178+0000] {dagbag.py:355} ERROR - Failed to import: /opt/airflow/dags/dag.py
Traceback (most recent call last):
  File "/home/airflow/.local/lib/python3.12/site-packages/airflow/models/dagbag.py", line 351, in parse
    loader.exec_module(new_module)
  File "<frozen importlib._bootstrap_external>", line 995, in exec_module
  File "<frozen importlib._bootstrap>", line 488, in _call_with_frames_removed
  File "/opt/airflow/dags/dag.py", line 8, in <module>
    with DAG(
         ^^^^
  File "/home/airflow/.local/lib/python3.12/site-packages/airflow/models/dag.py", line 519, in __init__
    validate_key(dag_id)
  File "/home/airflow/.local/lib/python3.12/site-packages/airflow/utils/helpers.py", line 57, in validate_key
    raise AirflowException(
airflow.exceptions.AirflowException: The key '' has to be made of alphanumeric characters, dashes, dots and underscores exclusively
[2024-09-16T21:41:18.180+0000] {processor.py:842} WARNING - No viable dags retrieved from /opt/airflow/dags/dag.py
[2024-09-16T21:41:18.199+0000] {processor.py:183} INFO - Processing /opt/airflow/dags/dag.py took 0.530 seconds
[2024-09-16T21:41:48.301+0000] {processor.py:161} INFO - Started process (PID=707) to work on /opt/airflow/dags/dag.py
[2024-09-16T21:41:48.301+0000] {processor.py:830} INFO - Processing file /opt/airflow/dags/dag.py for tasks to queue
[2024-09-16T21:41:48.303+0000] {logging_mixin.py:188} INFO - [2024-09-16T21:41:48.302+0000] {dagbag.py:545} INFO - Filling up the DagBag from /opt/airflow/dags/dag.py
[2024-09-16T21:41:48.738+0000] {logging_mixin.py:188} INFO - [2024-09-16T21:41:48.737+0000] {dagbag.py:355} ERROR - Failed to import: /opt/airflow/dags/dag.py
Traceback (most recent call last):
  File "/home/airflow/.local/lib/python3.12/site-packages/airflow/models/dagbag.py", line 351, in parse
    loader.exec_module(new_module)
  File "<frozen importlib._bootstrap_external>", line 995, in exec_module
  File "<frozen importlib._bootstrap>", line 488, in _call_with_frames_removed
  File "/opt/airflow/dags/dag.py", line 8, in <module>
    with DAG(
         ^^^^
  File "/home/airflow/.local/lib/python3.12/site-packages/airflow/models/dag.py", line 519, in __init__
    validate_key(dag_id)
  File "/home/airflow/.local/lib/python3.12/site-packages/airflow/utils/helpers.py", line 57, in validate_key
    raise AirflowException(
airflow.exceptions.AirflowException: The key '' has to be made of alphanumeric characters, dashes, dots and underscores exclusively
[2024-09-16T21:41:48.739+0000] {processor.py:842} WARNING - No viable dags retrieved from /opt/airflow/dags/dag.py
[2024-09-16T21:41:48.758+0000] {processor.py:183} INFO - Processing /opt/airflow/dags/dag.py took 0.461 seconds
[2024-09-16T21:42:18.875+0000] {processor.py:161} INFO - Started process (PID=715) to work on /opt/airflow/dags/dag.py
[2024-09-16T21:42:18.875+0000] {processor.py:830} INFO - Processing file /opt/airflow/dags/dag.py for tasks to queue
[2024-09-16T21:42:18.877+0000] {logging_mixin.py:188} INFO - [2024-09-16T21:42:18.877+0000] {dagbag.py:545} INFO - Filling up the DagBag from /opt/airflow/dags/dag.py
[2024-09-16T21:42:19.360+0000] {logging_mixin.py:188} INFO - [2024-09-16T21:42:19.358+0000] {dagbag.py:355} ERROR - Failed to import: /opt/airflow/dags/dag.py
Traceback (most recent call last):
  File "/home/airflow/.local/lib/python3.12/site-packages/airflow/models/dagbag.py", line 351, in parse
    loader.exec_module(new_module)
  File "<frozen importlib._bootstrap_external>", line 995, in exec_module
  File "<frozen importlib._bootstrap>", line 488, in _call_with_frames_removed
  File "/opt/airflow/dags/dag.py", line 8, in <module>
    with DAG(
         ^^^^
  File "/home/airflow/.local/lib/python3.12/site-packages/airflow/models/dag.py", line 519, in __init__
    validate_key(dag_id)
  File "/home/airflow/.local/lib/python3.12/site-packages/airflow/utils/helpers.py", line 57, in validate_key
    raise AirflowException(
airflow.exceptions.AirflowException: The key '' has to be made of alphanumeric characters, dashes, dots and underscores exclusively
[2024-09-16T21:42:19.360+0000] {processor.py:842} WARNING - No viable dags retrieved from /opt/airflow/dags/dag.py
[2024-09-16T21:42:19.379+0000] {processor.py:183} INFO - Processing /opt/airflow/dags/dag.py took 0.510 seconds
[2024-09-16T21:42:49.507+0000] {processor.py:161} INFO - Started process (PID=723) to work on /opt/airflow/dags/dag.py
[2024-09-16T21:42:49.507+0000] {processor.py:830} INFO - Processing file /opt/airflow/dags/dag.py for tasks to queue
[2024-09-16T21:42:49.509+0000] {logging_mixin.py:188} INFO - [2024-09-16T21:42:49.509+0000] {dagbag.py:545} INFO - Filling up the DagBag from /opt/airflow/dags/dag.py
[2024-09-16T21:42:49.950+0000] {logging_mixin.py:188} INFO - [2024-09-16T21:42:49.948+0000] {dagbag.py:355} ERROR - Failed to import: /opt/airflow/dags/dag.py
Traceback (most recent call last):
  File "/home/airflow/.local/lib/python3.12/site-packages/airflow/models/dagbag.py", line 351, in parse
    loader.exec_module(new_module)
  File "<frozen importlib._bootstrap_external>", line 995, in exec_module
  File "<frozen importlib._bootstrap>", line 488, in _call_with_frames_removed
  File "/opt/airflow/dags/dag.py", line 8, in <module>
    with DAG(
         ^^^^
  File "/home/airflow/.local/lib/python3.12/site-packages/airflow/models/dag.py", line 519, in __init__
    validate_key(dag_id)
  File "/home/airflow/.local/lib/python3.12/site-packages/airflow/utils/helpers.py", line 57, in validate_key
    raise AirflowException(
airflow.exceptions.AirflowException: The key '' has to be made of alphanumeric characters, dashes, dots and underscores exclusively
[2024-09-16T21:42:49.950+0000] {processor.py:842} WARNING - No viable dags retrieved from /opt/airflow/dags/dag.py
[2024-09-16T21:42:49.969+0000] {processor.py:183} INFO - Processing /opt/airflow/dags/dag.py took 0.466 seconds
[2024-09-16T21:43:20.085+0000] {processor.py:161} INFO - Started process (PID=730) to work on /opt/airflow/dags/dag.py
[2024-09-16T21:43:20.086+0000] {processor.py:830} INFO - Processing file /opt/airflow/dags/dag.py for tasks to queue
[2024-09-16T21:43:20.087+0000] {logging_mixin.py:188} INFO - [2024-09-16T21:43:20.087+0000] {dagbag.py:545} INFO - Filling up the DagBag from /opt/airflow/dags/dag.py
[2024-09-16T21:43:20.603+0000] {logging_mixin.py:188} INFO - [2024-09-16T21:43:20.601+0000] {dagbag.py:355} ERROR - Failed to import: /opt/airflow/dags/dag.py
Traceback (most recent call last):
  File "/home/airflow/.local/lib/python3.12/site-packages/airflow/models/dagbag.py", line 351, in parse
    loader.exec_module(new_module)
  File "<frozen importlib._bootstrap_external>", line 995, in exec_module
  File "<frozen importlib._bootstrap>", line 488, in _call_with_frames_removed
  File "/opt/airflow/dags/dag.py", line 8, in <module>
    with DAG(
         ^^^^
  File "/home/airflow/.local/lib/python3.12/site-packages/airflow/models/dag.py", line 519, in __init__
    validate_key(dag_id)
  File "/home/airflow/.local/lib/python3.12/site-packages/airflow/utils/helpers.py", line 57, in validate_key
    raise AirflowException(
airflow.exceptions.AirflowException: The key '' has to be made of alphanumeric characters, dashes, dots and underscores exclusively
[2024-09-16T21:43:20.603+0000] {processor.py:842} WARNING - No viable dags retrieved from /opt/airflow/dags/dag.py
[2024-09-16T21:43:20.624+0000] {processor.py:183} INFO - Processing /opt/airflow/dags/dag.py took 0.543 seconds
[2024-09-16T21:43:50.717+0000] {processor.py:161} INFO - Started process (PID=738) to work on /opt/airflow/dags/dag.py
[2024-09-16T21:43:50.718+0000] {processor.py:830} INFO - Processing file /opt/airflow/dags/dag.py for tasks to queue
[2024-09-16T21:43:50.719+0000] {logging_mixin.py:188} INFO - [2024-09-16T21:43:50.719+0000] {dagbag.py:545} INFO - Filling up the DagBag from /opt/airflow/dags/dag.py
[2024-09-16T21:43:51.155+0000] {logging_mixin.py:188} INFO - [2024-09-16T21:43:51.154+0000] {dagbag.py:355} ERROR - Failed to import: /opt/airflow/dags/dag.py
Traceback (most recent call last):
  File "/home/airflow/.local/lib/python3.12/site-packages/airflow/models/dagbag.py", line 351, in parse
    loader.exec_module(new_module)
  File "<frozen importlib._bootstrap_external>", line 995, in exec_module
  File "<frozen importlib._bootstrap>", line 488, in _call_with_frames_removed
  File "/opt/airflow/dags/dag.py", line 8, in <module>
    with DAG(
         ^^^^
  File "/home/airflow/.local/lib/python3.12/site-packages/airflow/models/dag.py", line 519, in __init__
    validate_key(dag_id)
  File "/home/airflow/.local/lib/python3.12/site-packages/airflow/utils/helpers.py", line 57, in validate_key
    raise AirflowException(
airflow.exceptions.AirflowException: The key '' has to be made of alphanumeric characters, dashes, dots and underscores exclusively
[2024-09-16T21:43:51.156+0000] {processor.py:842} WARNING - No viable dags retrieved from /opt/airflow/dags/dag.py
[2024-09-16T21:43:51.183+0000] {processor.py:183} INFO - Processing /opt/airflow/dags/dag.py took 0.472 seconds
[2024-09-16T21:44:21.299+0000] {processor.py:161} INFO - Started process (PID=747) to work on /opt/airflow/dags/dag.py
[2024-09-16T21:44:21.300+0000] {processor.py:830} INFO - Processing file /opt/airflow/dags/dag.py for tasks to queue
[2024-09-16T21:44:21.301+0000] {logging_mixin.py:188} INFO - [2024-09-16T21:44:21.301+0000] {dagbag.py:545} INFO - Filling up the DagBag from /opt/airflow/dags/dag.py
[2024-09-16T21:44:21.758+0000] {logging_mixin.py:188} INFO - [2024-09-16T21:44:21.757+0000] {dagbag.py:355} ERROR - Failed to import: /opt/airflow/dags/dag.py
Traceback (most recent call last):
  File "/home/airflow/.local/lib/python3.12/site-packages/airflow/models/dagbag.py", line 351, in parse
    loader.exec_module(new_module)
  File "<frozen importlib._bootstrap_external>", line 995, in exec_module
  File "<frozen importlib._bootstrap>", line 488, in _call_with_frames_removed
  File "/opt/airflow/dags/dag.py", line 8, in <module>
    with DAG(
         ^^^^
  File "/home/airflow/.local/lib/python3.12/site-packages/airflow/models/dag.py", line 519, in __init__
    validate_key(dag_id)
  File "/home/airflow/.local/lib/python3.12/site-packages/airflow/utils/helpers.py", line 57, in validate_key
    raise AirflowException(
airflow.exceptions.AirflowException: The key '' has to be made of alphanumeric characters, dashes, dots and underscores exclusively
[2024-09-16T21:44:21.759+0000] {processor.py:842} WARNING - No viable dags retrieved from /opt/airflow/dags/dag.py
[2024-09-16T21:44:21.786+0000] {processor.py:183} INFO - Processing /opt/airflow/dags/dag.py took 0.491 seconds
[2024-09-16T21:44:51.902+0000] {processor.py:161} INFO - Started process (PID=756) to work on /opt/airflow/dags/dag.py
[2024-09-16T21:44:51.902+0000] {processor.py:830} INFO - Processing file /opt/airflow/dags/dag.py for tasks to queue
[2024-09-16T21:44:51.904+0000] {logging_mixin.py:188} INFO - [2024-09-16T21:44:51.903+0000] {dagbag.py:545} INFO - Filling up the DagBag from /opt/airflow/dags/dag.py
[2024-09-16T21:44:52.379+0000] {logging_mixin.py:188} INFO - [2024-09-16T21:44:52.377+0000] {dagbag.py:355} ERROR - Failed to import: /opt/airflow/dags/dag.py
Traceback (most recent call last):
  File "/home/airflow/.local/lib/python3.12/site-packages/airflow/models/dagbag.py", line 351, in parse
    loader.exec_module(new_module)
  File "<frozen importlib._bootstrap_external>", line 995, in exec_module
  File "<frozen importlib._bootstrap>", line 488, in _call_with_frames_removed
  File "/opt/airflow/dags/dag.py", line 8, in <module>
    with DAG(
         ^^^^
  File "/home/airflow/.local/lib/python3.12/site-packages/airflow/models/dag.py", line 519, in __init__
    validate_key(dag_id)
  File "/home/airflow/.local/lib/python3.12/site-packages/airflow/utils/helpers.py", line 57, in validate_key
    raise AirflowException(
airflow.exceptions.AirflowException: The key '' has to be made of alphanumeric characters, dashes, dots and underscores exclusively
[2024-09-16T21:44:52.380+0000] {processor.py:842} WARNING - No viable dags retrieved from /opt/airflow/dags/dag.py
[2024-09-16T21:44:52.399+0000] {processor.py:183} INFO - Processing /opt/airflow/dags/dag.py took 0.502 seconds
[2024-09-16T21:45:22.495+0000] {processor.py:161} INFO - Started process (PID=764) to work on /opt/airflow/dags/dag.py
[2024-09-16T21:45:22.496+0000] {processor.py:830} INFO - Processing file /opt/airflow/dags/dag.py for tasks to queue
[2024-09-16T21:45:22.497+0000] {logging_mixin.py:188} INFO - [2024-09-16T21:45:22.497+0000] {dagbag.py:545} INFO - Filling up the DagBag from /opt/airflow/dags/dag.py
[2024-09-16T21:45:22.937+0000] {logging_mixin.py:188} INFO - [2024-09-16T21:45:22.936+0000] {dagbag.py:355} ERROR - Failed to import: /opt/airflow/dags/dag.py
Traceback (most recent call last):
  File "/home/airflow/.local/lib/python3.12/site-packages/airflow/models/dagbag.py", line 351, in parse
    loader.exec_module(new_module)
  File "<frozen importlib._bootstrap_external>", line 995, in exec_module
  File "<frozen importlib._bootstrap>", line 488, in _call_with_frames_removed
  File "/opt/airflow/dags/dag.py", line 8, in <module>
    with DAG(
         ^^^^
  File "/home/airflow/.local/lib/python3.12/site-packages/airflow/models/dag.py", line 519, in __init__
    validate_key(dag_id)
  File "/home/airflow/.local/lib/python3.12/site-packages/airflow/utils/helpers.py", line 57, in validate_key
    raise AirflowException(
airflow.exceptions.AirflowException: The key '' has to be made of alphanumeric characters, dashes, dots and underscores exclusively
[2024-09-16T21:45:22.938+0000] {processor.py:842} WARNING - No viable dags retrieved from /opt/airflow/dags/dag.py
[2024-09-16T21:45:22.956+0000] {processor.py:183} INFO - Processing /opt/airflow/dags/dag.py took 0.465 seconds
[2024-09-16T21:45:53.071+0000] {processor.py:161} INFO - Started process (PID=773) to work on /opt/airflow/dags/dag.py
[2024-09-16T21:45:53.072+0000] {processor.py:830} INFO - Processing file /opt/airflow/dags/dag.py for tasks to queue
[2024-09-16T21:45:53.073+0000] {logging_mixin.py:188} INFO - [2024-09-16T21:45:53.073+0000] {dagbag.py:545} INFO - Filling up the DagBag from /opt/airflow/dags/dag.py
[2024-09-16T21:45:53.514+0000] {logging_mixin.py:188} INFO - [2024-09-16T21:45:53.513+0000] {dagbag.py:355} ERROR - Failed to import: /opt/airflow/dags/dag.py
Traceback (most recent call last):
  File "/home/airflow/.local/lib/python3.12/site-packages/airflow/models/dagbag.py", line 351, in parse
    loader.exec_module(new_module)
  File "<frozen importlib._bootstrap_external>", line 995, in exec_module
  File "<frozen importlib._bootstrap>", line 488, in _call_with_frames_removed
  File "/opt/airflow/dags/dag.py", line 8, in <module>
    with DAG(
         ^^^^
  File "/home/airflow/.local/lib/python3.12/site-packages/airflow/models/dag.py", line 519, in __init__
    validate_key(dag_id)
  File "/home/airflow/.local/lib/python3.12/site-packages/airflow/utils/helpers.py", line 57, in validate_key
    raise AirflowException(
airflow.exceptions.AirflowException: The key '' has to be made of alphanumeric characters, dashes, dots and underscores exclusively
[2024-09-16T21:45:53.515+0000] {processor.py:842} WARNING - No viable dags retrieved from /opt/airflow/dags/dag.py
[2024-09-16T21:45:53.533+0000] {processor.py:183} INFO - Processing /opt/airflow/dags/dag.py took 0.466 seconds
[2024-09-16T21:46:23.652+0000] {processor.py:161} INFO - Started process (PID=781) to work on /opt/airflow/dags/dag.py
[2024-09-16T21:46:23.653+0000] {processor.py:830} INFO - Processing file /opt/airflow/dags/dag.py for tasks to queue
[2024-09-16T21:46:23.654+0000] {logging_mixin.py:188} INFO - [2024-09-16T21:46:23.654+0000] {dagbag.py:545} INFO - Filling up the DagBag from /opt/airflow/dags/dag.py
[2024-09-16T21:46:24.102+0000] {logging_mixin.py:188} INFO - [2024-09-16T21:46:24.100+0000] {dagbag.py:355} ERROR - Failed to import: /opt/airflow/dags/dag.py
Traceback (most recent call last):
  File "/home/airflow/.local/lib/python3.12/site-packages/airflow/models/dagbag.py", line 351, in parse
    loader.exec_module(new_module)
  File "<frozen importlib._bootstrap_external>", line 995, in exec_module
  File "<frozen importlib._bootstrap>", line 488, in _call_with_frames_removed
  File "/opt/airflow/dags/dag.py", line 8, in <module>
    with DAG(
         ^^^^
  File "/home/airflow/.local/lib/python3.12/site-packages/airflow/models/dag.py", line 519, in __init__
    validate_key(dag_id)
  File "/home/airflow/.local/lib/python3.12/site-packages/airflow/utils/helpers.py", line 57, in validate_key
    raise AirflowException(
airflow.exceptions.AirflowException: The key '' has to be made of alphanumeric characters, dashes, dots and underscores exclusively
[2024-09-16T21:46:24.102+0000] {processor.py:842} WARNING - No viable dags retrieved from /opt/airflow/dags/dag.py
[2024-09-16T21:46:24.137+0000] {processor.py:183} INFO - Processing /opt/airflow/dags/dag.py took 0.489 seconds
[2024-09-16T21:46:54.272+0000] {processor.py:161} INFO - Started process (PID=789) to work on /opt/airflow/dags/dag.py
[2024-09-16T21:46:54.273+0000] {processor.py:830} INFO - Processing file /opt/airflow/dags/dag.py for tasks to queue
[2024-09-16T21:46:54.274+0000] {logging_mixin.py:188} INFO - [2024-09-16T21:46:54.274+0000] {dagbag.py:545} INFO - Filling up the DagBag from /opt/airflow/dags/dag.py
[2024-09-16T21:46:54.827+0000] {logging_mixin.py:188} INFO - [2024-09-16T21:46:54.824+0000] {dagbag.py:355} ERROR - Failed to import: /opt/airflow/dags/dag.py
Traceback (most recent call last):
  File "/home/airflow/.local/lib/python3.12/site-packages/airflow/models/dagbag.py", line 351, in parse
    loader.exec_module(new_module)
  File "<frozen importlib._bootstrap_external>", line 995, in exec_module
  File "<frozen importlib._bootstrap>", line 488, in _call_with_frames_removed
  File "/opt/airflow/dags/dag.py", line 8, in <module>
    with DAG(
         ^^^^
  File "/home/airflow/.local/lib/python3.12/site-packages/airflow/models/dag.py", line 519, in __init__
    validate_key(dag_id)
  File "/home/airflow/.local/lib/python3.12/site-packages/airflow/utils/helpers.py", line 57, in validate_key
    raise AirflowException(
airflow.exceptions.AirflowException: The key '' has to be made of alphanumeric characters, dashes, dots and underscores exclusively
[2024-09-16T21:46:54.827+0000] {processor.py:842} WARNING - No viable dags retrieved from /opt/airflow/dags/dag.py
[2024-09-16T21:46:54.859+0000] {processor.py:183} INFO - Processing /opt/airflow/dags/dag.py took 0.591 seconds
[2024-09-16T21:47:24.982+0000] {processor.py:161} INFO - Started process (PID=798) to work on /opt/airflow/dags/dag.py
[2024-09-16T21:47:24.983+0000] {processor.py:830} INFO - Processing file /opt/airflow/dags/dag.py for tasks to queue
[2024-09-16T21:47:24.985+0000] {logging_mixin.py:188} INFO - [2024-09-16T21:47:24.984+0000] {dagbag.py:545} INFO - Filling up the DagBag from /opt/airflow/dags/dag.py
[2024-09-16T21:47:25.742+0000] {logging_mixin.py:188} INFO - [2024-09-16T21:47:25.731+0000] {dagbag.py:355} ERROR - Failed to import: /opt/airflow/dags/dag.py
Traceback (most recent call last):
  File "/home/airflow/.local/lib/python3.12/site-packages/airflow/models/dagbag.py", line 351, in parse
    loader.exec_module(new_module)
  File "<frozen importlib._bootstrap_external>", line 995, in exec_module
  File "<frozen importlib._bootstrap>", line 488, in _call_with_frames_removed
  File "/opt/airflow/dags/dag.py", line 8, in <module>
    with DAG(
         ^^^^
  File "/home/airflow/.local/lib/python3.12/site-packages/airflow/models/dag.py", line 519, in __init__
    validate_key(dag_id)
  File "/home/airflow/.local/lib/python3.12/site-packages/airflow/utils/helpers.py", line 57, in validate_key
    raise AirflowException(
airflow.exceptions.AirflowException: The key '' has to be made of alphanumeric characters, dashes, dots and underscores exclusively
[2024-09-16T21:47:25.748+0000] {processor.py:842} WARNING - No viable dags retrieved from /opt/airflow/dags/dag.py
[2024-09-16T21:47:25.805+0000] {processor.py:183} INFO - Processing /opt/airflow/dags/dag.py took 0.830 seconds
[2024-09-16T21:47:55.949+0000] {processor.py:161} INFO - Started process (PID=807) to work on /opt/airflow/dags/dag.py
[2024-09-16T21:47:55.950+0000] {processor.py:830} INFO - Processing file /opt/airflow/dags/dag.py for tasks to queue
[2024-09-16T21:47:55.951+0000] {logging_mixin.py:188} INFO - [2024-09-16T21:47:55.951+0000] {dagbag.py:545} INFO - Filling up the DagBag from /opt/airflow/dags/dag.py
[2024-09-16T21:47:56.391+0000] {logging_mixin.py:188} INFO - [2024-09-16T21:47:56.389+0000] {dagbag.py:355} ERROR - Failed to import: /opt/airflow/dags/dag.py
Traceback (most recent call last):
  File "/home/airflow/.local/lib/python3.12/site-packages/airflow/models/dagbag.py", line 351, in parse
    loader.exec_module(new_module)
  File "<frozen importlib._bootstrap_external>", line 995, in exec_module
  File "<frozen importlib._bootstrap>", line 488, in _call_with_frames_removed
  File "/opt/airflow/dags/dag.py", line 8, in <module>
    with DAG(
         ^^^^
  File "/home/airflow/.local/lib/python3.12/site-packages/airflow/models/dag.py", line 519, in __init__
    validate_key(dag_id)
  File "/home/airflow/.local/lib/python3.12/site-packages/airflow/utils/helpers.py", line 57, in validate_key
    raise AirflowException(
airflow.exceptions.AirflowException: The key '' has to be made of alphanumeric characters, dashes, dots and underscores exclusively
[2024-09-16T21:47:56.392+0000] {processor.py:842} WARNING - No viable dags retrieved from /opt/airflow/dags/dag.py
[2024-09-16T21:47:56.417+0000] {processor.py:183} INFO - Processing /opt/airflow/dags/dag.py took 0.474 seconds
[2024-09-16T21:48:26.547+0000] {processor.py:161} INFO - Started process (PID=815) to work on /opt/airflow/dags/dag.py
[2024-09-16T21:48:26.548+0000] {processor.py:830} INFO - Processing file /opt/airflow/dags/dag.py for tasks to queue
[2024-09-16T21:48:26.550+0000] {logging_mixin.py:188} INFO - [2024-09-16T21:48:26.550+0000] {dagbag.py:545} INFO - Filling up the DagBag from /opt/airflow/dags/dag.py
[2024-09-16T21:48:27.036+0000] {logging_mixin.py:188} INFO - [2024-09-16T21:48:27.034+0000] {dagbag.py:355} ERROR - Failed to import: /opt/airflow/dags/dag.py
Traceback (most recent call last):
  File "/home/airflow/.local/lib/python3.12/site-packages/airflow/models/dagbag.py", line 351, in parse
    loader.exec_module(new_module)
  File "<frozen importlib._bootstrap_external>", line 995, in exec_module
  File "<frozen importlib._bootstrap>", line 488, in _call_with_frames_removed
  File "/opt/airflow/dags/dag.py", line 8, in <module>
    with DAG(
         ^^^^
  File "/home/airflow/.local/lib/python3.12/site-packages/airflow/models/dag.py", line 519, in __init__
    validate_key(dag_id)
  File "/home/airflow/.local/lib/python3.12/site-packages/airflow/utils/helpers.py", line 57, in validate_key
    raise AirflowException(
airflow.exceptions.AirflowException: The key '' has to be made of alphanumeric characters, dashes, dots and underscores exclusively
[2024-09-16T21:48:27.037+0000] {processor.py:842} WARNING - No viable dags retrieved from /opt/airflow/dags/dag.py
[2024-09-16T21:48:27.077+0000] {processor.py:183} INFO - Processing /opt/airflow/dags/dag.py took 0.536 seconds
[2024-09-16T21:48:57.198+0000] {processor.py:161} INFO - Started process (PID=824) to work on /opt/airflow/dags/dag.py
[2024-09-16T21:48:57.199+0000] {processor.py:830} INFO - Processing file /opt/airflow/dags/dag.py for tasks to queue
[2024-09-16T21:48:57.203+0000] {logging_mixin.py:188} INFO - [2024-09-16T21:48:57.203+0000] {dagbag.py:545} INFO - Filling up the DagBag from /opt/airflow/dags/dag.py
[2024-09-16T21:48:57.895+0000] {logging_mixin.py:188} INFO - [2024-09-16T21:48:57.893+0000] {dagbag.py:355} ERROR - Failed to import: /opt/airflow/dags/dag.py
Traceback (most recent call last):
  File "/home/airflow/.local/lib/python3.12/site-packages/airflow/models/dagbag.py", line 351, in parse
    loader.exec_module(new_module)
  File "<frozen importlib._bootstrap_external>", line 995, in exec_module
  File "<frozen importlib._bootstrap>", line 488, in _call_with_frames_removed
  File "/opt/airflow/dags/dag.py", line 8, in <module>
    with DAG(
         ^^^^
  File "/home/airflow/.local/lib/python3.12/site-packages/airflow/models/dag.py", line 519, in __init__
    validate_key(dag_id)
  File "/home/airflow/.local/lib/python3.12/site-packages/airflow/utils/helpers.py", line 57, in validate_key
    raise AirflowException(
airflow.exceptions.AirflowException: The key '' has to be made of alphanumeric characters, dashes, dots and underscores exclusively
[2024-09-16T21:48:57.896+0000] {processor.py:842} WARNING - No viable dags retrieved from /opt/airflow/dags/dag.py
[2024-09-16T21:48:57.921+0000] {processor.py:183} INFO - Processing /opt/airflow/dags/dag.py took 0.729 seconds
[2024-09-16T21:49:28.068+0000] {processor.py:161} INFO - Started process (PID=832) to work on /opt/airflow/dags/dag.py
[2024-09-16T21:49:28.069+0000] {processor.py:830} INFO - Processing file /opt/airflow/dags/dag.py for tasks to queue
[2024-09-16T21:49:28.071+0000] {logging_mixin.py:188} INFO - [2024-09-16T21:49:28.071+0000] {dagbag.py:545} INFO - Filling up the DagBag from /opt/airflow/dags/dag.py
[2024-09-16T21:49:28.529+0000] {logging_mixin.py:188} INFO - [2024-09-16T21:49:28.527+0000] {dagbag.py:355} ERROR - Failed to import: /opt/airflow/dags/dag.py
Traceback (most recent call last):
  File "/home/airflow/.local/lib/python3.12/site-packages/airflow/models/dagbag.py", line 351, in parse
    loader.exec_module(new_module)
  File "<frozen importlib._bootstrap_external>", line 995, in exec_module
  File "<frozen importlib._bootstrap>", line 488, in _call_with_frames_removed
  File "/opt/airflow/dags/dag.py", line 8, in <module>
    with DAG(
         ^^^^
  File "/home/airflow/.local/lib/python3.12/site-packages/airflow/models/dag.py", line 519, in __init__
    validate_key(dag_id)
  File "/home/airflow/.local/lib/python3.12/site-packages/airflow/utils/helpers.py", line 57, in validate_key
    raise AirflowException(
airflow.exceptions.AirflowException: The key '' has to be made of alphanumeric characters, dashes, dots and underscores exclusively
[2024-09-16T21:49:28.530+0000] {processor.py:842} WARNING - No viable dags retrieved from /opt/airflow/dags/dag.py
[2024-09-16T21:49:28.548+0000] {processor.py:183} INFO - Processing /opt/airflow/dags/dag.py took 0.488 seconds
[2024-09-16T21:49:58.671+0000] {processor.py:161} INFO - Started process (PID=841) to work on /opt/airflow/dags/dag.py
[2024-09-16T21:49:58.672+0000] {processor.py:830} INFO - Processing file /opt/airflow/dags/dag.py for tasks to queue
[2024-09-16T21:49:58.674+0000] {logging_mixin.py:188} INFO - [2024-09-16T21:49:58.673+0000] {dagbag.py:545} INFO - Filling up the DagBag from /opt/airflow/dags/dag.py
[2024-09-16T21:49:59.161+0000] {logging_mixin.py:188} INFO - [2024-09-16T21:49:59.159+0000] {dagbag.py:355} ERROR - Failed to import: /opt/airflow/dags/dag.py
Traceback (most recent call last):
  File "/home/airflow/.local/lib/python3.12/site-packages/airflow/models/dagbag.py", line 351, in parse
    loader.exec_module(new_module)
  File "<frozen importlib._bootstrap_external>", line 995, in exec_module
  File "<frozen importlib._bootstrap>", line 488, in _call_with_frames_removed
  File "/opt/airflow/dags/dag.py", line 8, in <module>
    with DAG(
         ^^^^
  File "/home/airflow/.local/lib/python3.12/site-packages/airflow/models/dag.py", line 519, in __init__
    validate_key(dag_id)
  File "/home/airflow/.local/lib/python3.12/site-packages/airflow/utils/helpers.py", line 57, in validate_key
    raise AirflowException(
airflow.exceptions.AirflowException: The key '' has to be made of alphanumeric characters, dashes, dots and underscores exclusively
[2024-09-16T21:49:59.162+0000] {processor.py:842} WARNING - No viable dags retrieved from /opt/airflow/dags/dag.py
[2024-09-16T21:49:59.180+0000] {processor.py:183} INFO - Processing /opt/airflow/dags/dag.py took 0.514 seconds
[2024-09-16T21:50:29.263+0000] {processor.py:161} INFO - Started process (PID=849) to work on /opt/airflow/dags/dag.py
[2024-09-16T21:50:29.264+0000] {processor.py:830} INFO - Processing file /opt/airflow/dags/dag.py for tasks to queue
[2024-09-16T21:50:29.266+0000] {logging_mixin.py:188} INFO - [2024-09-16T21:50:29.266+0000] {dagbag.py:545} INFO - Filling up the DagBag from /opt/airflow/dags/dag.py
[2024-09-16T21:50:29.706+0000] {logging_mixin.py:188} INFO - [2024-09-16T21:50:29.704+0000] {dagbag.py:355} ERROR - Failed to import: /opt/airflow/dags/dag.py
Traceback (most recent call last):
  File "/home/airflow/.local/lib/python3.12/site-packages/airflow/models/dagbag.py", line 351, in parse
    loader.exec_module(new_module)
  File "<frozen importlib._bootstrap_external>", line 995, in exec_module
  File "<frozen importlib._bootstrap>", line 488, in _call_with_frames_removed
  File "/opt/airflow/dags/dag.py", line 8, in <module>
    with DAG(
         ^^^^
  File "/home/airflow/.local/lib/python3.12/site-packages/airflow/models/dag.py", line 519, in __init__
    validate_key(dag_id)
  File "/home/airflow/.local/lib/python3.12/site-packages/airflow/utils/helpers.py", line 57, in validate_key
    raise AirflowException(
airflow.exceptions.AirflowException: The key '' has to be made of alphanumeric characters, dashes, dots and underscores exclusively
[2024-09-16T21:50:29.707+0000] {processor.py:842} WARNING - No viable dags retrieved from /opt/airflow/dags/dag.py
[2024-09-16T21:50:29.726+0000] {processor.py:183} INFO - Processing /opt/airflow/dags/dag.py took 0.467 seconds
[2024-09-16T21:50:59.844+0000] {processor.py:161} INFO - Started process (PID=857) to work on /opt/airflow/dags/dag.py
[2024-09-16T21:50:59.844+0000] {processor.py:830} INFO - Processing file /opt/airflow/dags/dag.py for tasks to queue
[2024-09-16T21:50:59.846+0000] {logging_mixin.py:188} INFO - [2024-09-16T21:50:59.846+0000] {dagbag.py:545} INFO - Filling up the DagBag from /opt/airflow/dags/dag.py
[2024-09-16T21:51:00.298+0000] {logging_mixin.py:188} INFO - [2024-09-16T21:51:00.297+0000] {dagbag.py:355} ERROR - Failed to import: /opt/airflow/dags/dag.py
Traceback (most recent call last):
  File "/home/airflow/.local/lib/python3.12/site-packages/airflow/models/dagbag.py", line 351, in parse
    loader.exec_module(new_module)
  File "<frozen importlib._bootstrap_external>", line 995, in exec_module
  File "<frozen importlib._bootstrap>", line 488, in _call_with_frames_removed
  File "/opt/airflow/dags/dag.py", line 8, in <module>
    with DAG(
         ^^^^
  File "/home/airflow/.local/lib/python3.12/site-packages/airflow/models/dag.py", line 519, in __init__
    validate_key(dag_id)
  File "/home/airflow/.local/lib/python3.12/site-packages/airflow/utils/helpers.py", line 57, in validate_key
    raise AirflowException(
airflow.exceptions.AirflowException: The key '' has to be made of alphanumeric characters, dashes, dots and underscores exclusively
[2024-09-16T21:51:00.299+0000] {processor.py:842} WARNING - No viable dags retrieved from /opt/airflow/dags/dag.py
[2024-09-16T21:51:00.318+0000] {processor.py:183} INFO - Processing /opt/airflow/dags/dag.py took 0.479 seconds
